Workbook

Sheet Capa
A1: Ações | C1: Atualizado em | D1: =TODAY() -> 46073 | E1: Vídeo: Como usar a planilha | AP1: =$D$1-365 -> 45708 | AQ1: =$D$1-30 -> 46043
C4: Ações | D4: Vídeo: Como usar a planilha
A5: 5 | F5: INDICADORES FUNDAMENTALISTAS => | M5: Ideal é MAIOR que 4% | N5: Ideal é Entre 10 e 15 | O5: Ideal é Maior de 1,5 | T5: Menor melhor. Quer dizer gera caixa para enfrentar a crise | W5: Ideal <0,5 Aceitável <1
A6: TICKER | B6: Empresa | C6: Setor | D6: SubSetor | E6: Segmento | F6: PRECO ATUAL Graph 30 Dias | I6: Cotação Máxima 12 meses | L6: Queda do Máximo | M6: DY | N6: P/L | O6: P/VP | P6: P/ATIVOS | Q6: MARGEM BRUTA | R6: MARGEM EBIT | S6: MARG. LIQUIDA | T6: P/EBIT | U6: EV/EBIT | V6: DIVIDA LIQUIDA / EBIT | W6: DIV. LIQ. / PATRI. | X6: PSR | Y6: P/CAP. GIRO | Z6: P. AT CIR. LIQ. | AA6: LIQ. CORRENTE | AB6: ROE | AC6: ROA | AD6: ROIC | AE6: PATRIMONIO / ATIVOS | AF6: PASSIVOS / ATIVOS | AG6: GIRO ATIVOS | AH6: CAGR RECEITAS 5 ANOS | AI6: CAGR LUCROS 5 ANOS | AJ6: LIQUIDEZ MEDIA DIARIA | AK6: Alta | AL6: Baixa | AM6: Percentual de Curva | AN6: Volume | AO6: Preço Fechamento Anterior
A7: ='Dados StatusInvest'!A2:A621 -> AESB3 | B7: =IFERROR(__xludf.DUMMYFUNCTION("IFERROR((GOOGLEFINANCE(A7,""name"")),"""")"),"") | C7: =IFERROR((VLOOKUP(LEFT($A7,4),Setor!$A:$E,3,0)),"") | D7: =IFERROR((VLOOKUP(LEFT($A7,4),Setor!$A:$E,4,0)),"") | E7: =IFERROR((VLOOKUP(LEFT($A7,4),Setor!$A:$E,5,0)),"") | F7: =IFERROR(__xludf.DUMMYFUNCTION("IFERROR((GOOGLEFINANCE(A7)),"""")"),"") | G7: =IFERROR(__xludf.DUMMYFUNCTION("IFERROR((sparkline(GOOGLEFINANCE($A7,""price"",TODAY()-30,TODAY(),""DAILY""),{""charttype"",""line"";""linewidth"",1;""color"",""#5f88cc""})),"""")"),"") | H7: =IFERROR(__xludf.DUMMYFUNCTION("IFERROR((((GOOGLEFINANCE(A7))-(INDEX(GoogleFinance(A7,""PRICE"",$AQ$1),2,2)))/(INDEX(GoogleFinance(A7,""PRICE"",$AQ$1),2,2))),"""")"),"") | I7: =IFERROR(__xludf.DUMMYFUNCTION("IFERROR((GOOGLEFINANCE($A7,""high52"")),"""")"),"") | J7: =IFERROR(__xludf.DUMMYFUNCTION("IFERROR((sparkline(GOOGLEFINANCE($A7,""price"",TODAY()-365,TODAY(),""DAILY""),{""charttype"",""line"";""linewidth"",1;""color"",""#5f88cc""})),"""")"),"") | K7: =IFERROR(__xludf.DUMMYFUNCTION("IFERROR((((GOOGLEFINANCE(A7))-(INDEX(GoogleFinance(A7,""PRICE"",$AP$1),2,2)))/(INDEX(GoogleFinance(A7,""PRICE"",$AP$1),2,2))),"""")"),"") | L7: =IFERROR(((F7-I7)/I7),0) -> 0 | M7: =IFERROR((VLOOKUP($A7,'Dados StatusInvest'!$A:$AZ,COLUMN(M7)-$A$5,0)*VLOOKUP($A7,'Dados StatusInvest'!$A:$AZ,2,0)/$F7/100),0) -> 0 | N7: =IFERROR((VLOOKUP($A7,'Dados StatusInvest'!$A:$AZ,COLUMN(N7)-$A$5,0)/VLOOKUP($A7,'Dados StatusInvest'!$A:$AZ,2,0)*$F7),"") -> 0 | O7: =IFERROR((VLOOKUP($A7,'Dados StatusInvest'!$A:$AZ,COLUMN(O7)-$A$5,0)/VLOOKUP($A7,'Dados StatusInvest'!$A:$AZ,2,0)*$F7),0) -> 0 | P7: =IFERROR((VLOOKUP($A7,'Dados StatusInvest'!$A:$AZ,COLUMN(P7)-$A$5,0)/VLOOKUP($A7,'Dados StatusInvest'!$A:$AZ,2,0)*$F7),0) -> 0 | Q7: =IFERROR((VLOOKUP($A7,'Dados StatusInvest'!$A:$AZ,COLUMN(Q7)-$A$5,0)/100),0) -> 0.103 | R7: =VLOOKUP($A7,'Dados StatusInvest'!$A:$AZ,COLUMN(R7)-$A$5,0) -> 2.32 | S7: =IFERROR((VLOOKUP($A7,'Dados StatusInvest'!$A:$AZ,COLUMN(S7)-$A$5,0)),0) -> 1.89 | T7: =IFERROR((VLOOKUP($A7,'Dados StatusInvest'!$A:$AZ,COLUMN(T7)-$A$5,0)/VLOOKUP($A7,'Dados StatusInvest'!$A:$AZ,2,0)*$F7),0) -> 0 | U7: =IFERROR((VLOOKUP($A7,'Dados StatusInvest'!$A:$AZ,COLUMN(U7)-$A$5,0)-VLOOKUP($A7,'Dados StatusInvest'!$A:$AZ,COLUMN(U7)-$A$5-1,0)+T7),0) -> 50.08 | V7: =IFERROR((VLOOKUP($A7,'Dados StatusInvest'!$A:$AZ,COLUMN(V7)-$A$5,0)),0) -> 0.95 | W7: =IFERROR((VLOOKUP($A7,'Dados StatusInvest'!$A:$AZ,COLUMN(W7)-$A$5,0)),0) -> -12.23 | X7: =IFERROR((VLOOKUP($A7,'Dados StatusInvest'!$A:$AZ,COLUMN(X7)-$A$5,0)/VLOOKUP($A7,'Dados StatusInvest'!$A:$AZ,2,0)*$F7),0) -> 0 | Y7: =IFERROR((VLOOKUP($A7,'Dados StatusInvest'!$A:$AZ,COLUMN(Y7)-$A$5,0)/VLOOKUP($A7,'Dados StatusInvest'!$A:$AZ,2,0)*$F7),0) -> 0 | Z7: =IFERROR((VLOOKUP($A7,'Dados StatusInvest'!$A:$AZ,COLUMN(Z7)-$A$5,0)),0) -> 0.21 | AA7: =IFERROR((VLOOKUP($A7,'Dados StatusInvest'!$A:$AZ,COLUMN(AA7)-$A$5,0)),0) -> 0.73 | AB7: =IFERROR((VLOOKUP($A7,'Dados StatusInvest'!$A:$AZ,COLUMN(AB7)-$A$5,0)),0) -> 0.2 | AC7: =IFERROR((VLOOKUP($A7,'Dados StatusInvest'!$A:$AZ,COLUMN(AC7)-$A$5,0)),0) -> 0 | AD7: =IFERROR((VLOOKUP($A7,'Dados StatusInvest'!$A:$AZ,COLUMN(AD7)-$A$5,0)),0) -> 0 | AE7: =IFERROR((VLOOKUP($A7,'Dados StatusInvest'!$A:$AZ,COLUMN(AE7)-$A$5,0)),0) -> 13684494 | AF7: =IFERROR((VLOOKUP($A7,'Dados StatusInvest'!$A:$AZ,COLUMN(AF7)-$A$5,0)),0) -> 4.52 | AG7: =IFERROR((VLOOKUP($A7,'Dados StatusInvest'!$A:$AZ,COLUMN(AG7)-$A$5,0)),0) -> -0.55 | ... AJ7: =IFERROR((VLOOKUP($A7,'Dados StatusInvest'!$A:$AZ,COLUMN(AJ7)-$A$5,0)),0) | AK7: =IFERROR(__xludf.DUMMYFUNCTION("IFERROR(GOOGLEFINANCE($A7,""high""),"""")"),"") | AL7: =IFERROR(__xludf.DUMMYFUNCTION("IFERROR(GOOGLEFINANCE($A7,""low""),"""")"),"") | AM7: =IFERROR(((AK7-AL7)/AL7),0) -> 0 | AN7: =IFERROR(__xludf.DUMMYFUNCTION("IFERROR((GOOGLEFINANCE($A7,""volume"")),0)"),0.0) -> 0 | AO7: =IFERROR(__xludf.DUMMYFUNCTION("IFERROR((GOOGLEFINANCE($A7,""closeyest"")),"""")"),"") | AP7: =IFERROR(__xludf.DUMMYFUNCTION("IFERROR((GOOGLEFINANCE($A7,""shares"")),"""")"),"")
A8: ='Dados StatusInvest'!A3:A622 -> AFLT3 | B8: =IFERROR(__xludf.DUMMYFUNCTION("IFERROR((GOOGLEFINANCE(A8,""name"")),"""")"),"Afluente Transmissao de Energia Eltrc SA") -> Afluente Transmissao de Energia Eltrc SA | C8: =IFERROR((VLOOKUP(LEFT($A8,4),Setor!$A:$E,3,0)),"") -> Utilidade Pública | D8: =IFERROR((VLOOKUP(LEFT($A8,4),Setor!$A:$E,4,0)),"") -> Energia Elétrica | E8: =IFERROR((VLOOKUP(LEFT($A8,4),Setor!$A:$E,5,0)),"") -> Energia Elétrica | F8: =IFERROR(__xludf.DUMMYFUNCTION("IFERROR((GOOGLEFINANCE(A8)),"""")"),7.39) -> 7.39 | G8: =IFERROR(__xludf.DUMMYFUNCTION("IFERROR((sparkline(GOOGLEFINANCE($A8,""price"",TODAY()-30,TODAY(),""DAILY""),{""charttype"",""line"";""linewidth"",1;""color"",""#5f88cc""})),"""")"),"") | H8: =IFERROR(__xludf.DUMMYFUNCTION("IFERROR((((GOOGLEFINANCE(A8))-(INDEX(GoogleFinance(A8,""PRICE"",$AQ$1),2,2)))/(INDEX(GoogleFinance(A8,""PRICE"",$AQ$1),2,2))),"""")"),0.005442176870748304) -> 0.0054421769 | I8: =IFERROR(__xludf.DUMMYFUNCTION("IFERROR((GOOGLEFINANCE($A8,""high52"")),"""")"),7.84) -> 7.84 | J8: =IFERROR(__xludf.DUMMYFUNCTION("IFERROR((sparkline(GOOGLEFINANCE($A8,""price"",TODAY()-365,TODAY(),""DAILY""),{""charttype"",""line"";""linewidth"",1;""color"",""#5f88cc""})),"""")"),"") | K8: =IFERROR(__xludf.DUMMYFUNCTION("IFERROR((((GOOGLEFINANCE(A8))-(INDEX(GoogleFinance(A8,""PRICE"",$AP$1),2,2)))/(INDEX(GoogleFinance(A8,""PRICE"",$AP$1),2,2))),"""")"),0.042313117066290526) -> 0.042313117 | L8: =IFERROR(((F8-I8)/I8),0) -> -0.057397959 | M8: =IFERROR((VLOOKUP($A8,'Dados StatusInvest'!$A:$AZ,COLUMN(M8)-$A$5,0)*VLOOKUP($A8,'Dados StatusInvest'!$A:$AZ,2,0)/$F8/100),0) -> 0.6147 | N8: =IFERROR((VLOOKUP($A8,'Dados StatusInvest'!$A:$AZ,COLUMN(N8)-$A$5,0)/VLOOKUP($A8,'Dados StatusInvest'!$A:$AZ,2,0)*$F8),"") -> 42.8 | O8: =IFERROR((VLOOKUP($A8,'Dados StatusInvest'!$A:$AZ,COLUMN(O8)-$A$5,0)/VLOOKUP($A8,'Dados StatusInvest'!$A:$AZ,2,0)*$F8),0) -> 9.31 | P8: =IFERROR((VLOOKUP($A8,'Dados StatusInvest'!$A:$AZ,COLUMN(P8)-$A$5,0)/VLOOKUP($A8,'Dados StatusInvest'!$A:$AZ,2,0)*$F8),0) -> 9.1 | Q8: =IFERROR((VLOOKUP($A8,'Dados StatusInvest'!$A:$AZ,COLUMN(Q8)-$A$5,0)/100),0) -> -0.0021 | R8: =VLOOKUP($A8,'Dados StatusInvest'!$A:$AZ,COLUMN(R8)-$A$5,0) -> -0.04 | S8: =IFERROR((VLOOKUP($A8,'Dados StatusInvest'!$A:$AZ,COLUMN(S8)-$A$5,0)),0) -> 5.72 | T8: =IFERROR((VLOOKUP($A8,'Dados StatusInvest'!$A:$AZ,COLUMN(T8)-$A$5,0)/VLOOKUP($A8,'Dados StatusInvest'!$A:$AZ,2,0)*$F8),0) -> 5.92 | U8: =IFERROR((VLOOKUP($A8,'Dados StatusInvest'!$A:$AZ,COLUMN(U8)-$A$5,0)-VLOOKUP($A8,'Dados StatusInvest'!$A:$AZ,COLUMN(U8)-$A$5-1,0)+T8),0) -> -1.82 | V8: =IFERROR((VLOOKUP($A8,'Dados StatusInvest'!$A:$AZ,COLUMN(V8)-$A$5,0)),0) -> 2.9 | W8: =IFERROR((VLOOKUP($A8,'Dados StatusInvest'!$A:$AZ,COLUMN(W8)-$A$5,0)),0) -> 13.65 | X8: =IFERROR((VLOOKUP($A8,'Dados StatusInvest'!$A:$AZ,COLUMN(X8)-$A$5,0)/VLOOKUP($A8,'Dados StatusInvest'!$A:$AZ,2,0)*$F8),0) -> 9.25 | Y8: =IFERROR((VLOOKUP($A8,'Dados StatusInvest'!$A:$AZ,COLUMN(Y8)-$A$5,0)/VLOOKUP($A8,'Dados StatusInvest'!$A:$AZ,2,0)*$F8),0) -> 13.92 | Z8: =IFERROR((VLOOKUP($A8,'Dados StatusInvest'!$A:$AZ,COLUMN(Z8)-$A$5,0)),0) -> 0.68 | AA8: =IFERROR((VLOOKUP($A8,'Dados StatusInvest'!$A:$AZ,COLUMN(AA8)-$A$5,0)),0) -> 0.32 | AB8: =IFERROR((VLOOKUP($A8,'Dados StatusInvest'!$A:$AZ,COLUMN(AB8)-$A$5,0)),0) -> 0.22 | AC8: =IFERROR((VLOOKUP($A8,'Dados StatusInvest'!$A:$AZ,COLUMN(AC8)-$A$5,0)),0) -> 17.36 | AD8: =IFERROR((VLOOKUP($A8,'Dados StatusInvest'!$A:$AZ,COLUMN(AD8)-$A$5,0)),0) -> 6.66 | AE8: =IFERROR((VLOOKUP($A8,'Dados StatusInvest'!$A:$AZ,COLUMN(AE8)-$A$5,0)),0) -> 2146.31 | AF8: =IFERROR((VLOOKUP($A8,'Dados StatusInvest'!$A:$AZ,COLUMN(AF8)-$A$5,0)),0) -> 4.05 | AG8: =IFERROR((VLOOKUP($A8,'Dados StatusInvest'!$A:$AZ,COLUMN(AG8)-$A$5,0)),0) -> 0.55 | ... AJ8: =IFERROR((VLOOKUP($A8,'Dados StatusInvest'!$A:$AZ,COLUMN(AJ8)-$A$5,0)),0) | AK8: =IFERROR(__xludf.DUMMYFUNCTION("IFERROR(GOOGLEFINANCE($A8,""high""),"""")"),"") | AL8: =IFERROR(__xludf.DUMMYFUNCTION("IFERROR(GOOGLEFINANCE($A8,""low""),"""")"),"") | AM8: =IFERROR(((AK8-AL8)/AL8),0) -> 0 | AN8: =IFERROR(__xludf.DUMMYFUNCTION("IFERROR((GOOGLEFINANCE($A8,""volume"")),0)"),0.0) -> 0 | AO8: =IFERROR(__xludf.DUMMYFUNCTION("IFERROR((GOOGLEFINANCE($A8,""closeyest"")),"""")"),7.39) -> 7.39 | AP8: =IFERROR(__xludf.DUMMYFUNCTION("IFERROR((GOOGLEFINANCE($A8,""shares"")),"""")"),6.30847E7) -> 63084700
A9: ='Dados StatusInvest'!A4:A623 -> AGRO3 | B9: =IFERROR(__xludf.DUMMYFUNCTION("IFERROR((GOOGLEFINANCE(A9,""name"")),"""")"),"BrasilAgro - Companhia Brslr d Prprd Agr") -> BrasilAgro - Companhia Brslr d Prprd Agr | C9: =IFERROR((VLOOKUP(LEFT($A9,4),Setor!$A:$E,3,0)),"") -> Consumo não Cíclico | D9: =IFERROR((VLOOKUP(LEFT($A9,4),Setor!$A:$E,4,0)),"") -> Agropecuária | E9: =IFERROR((VLOOKUP(LEFT($A9,4),Setor!$A:$E,5,0)),"") -> Agricultura | F9: =IFERROR(__xludf.DUMMYFUNCTION("IFERROR((GOOGLEFINANCE(A9)),"""")"),20.24) -> 20.24 | G9: =IFERROR(__xludf.DUMMYFUNCTION("IFERROR((sparkline(GOOGLEFINANCE($A9,""price"",TODAY()-30,TODAY(),""DAILY""),{""charttype"",""line"";""linewidth"",1;""color"",""#5f88cc""})),"""")"),"") | H9: =IFERROR(__xludf.DUMMYFUNCTION("IFERROR((((GOOGLEFINANCE(A9))-(INDEX(GoogleFinance(A9,""PRICE"",$AQ$1),2,2)))/(INDEX(GoogleFinance(A9,""PRICE"",$AQ$1),2,2))),"""")"),-0.0434782608695653) -> -0.043478261 | I9: =IFERROR(__xludf.DUMMYFUNCTION("IFERROR((GOOGLEFINANCE($A9,""high52"")),"""")"),22.21) -> 22.21 | J9: =IFERROR(__xludf.DUMMYFUNCTION("IFERROR((sparkline(GOOGLEFINANCE($A9,""price"",TODAY()-365,TODAY(),""DAILY""),{""charttype"",""line"";""linewidth"",1;""color"",""#5f88cc""})),"""")"),"") | K9: =IFERROR(__xludf.DUMMYFUNCTION("IFERROR((((GOOGLEFINANCE(A9))-(INDEX(GoogleFinance(A9,""PRICE"",$AP$1),2,2)))/(INDEX(GoogleFinance(A9,""PRICE"",$AP$1),2,2))),"""")"),-0.043026004728132394) -> -0.043026005 | L9: =IFERROR(((F9-I9)/I9),0) -> -0.088698784 | M9: =IFERROR((VLOOKUP($A9,'Dados StatusInvest'!$A:$AZ,COLUMN(M9)-$A$5,0)*VLOOKUP($A9,'Dados StatusInvest'!$A:$AZ,2,0)/$F9/100),0) -> 0.019619368 | N9: =IFERROR((VLOOKUP($A9,'Dados StatusInvest'!$A:$AZ,COLUMN(N9)-$A$5,0)/VLOOKUP($A9,'Dados StatusInvest'!$A:$AZ,2,0)*$F9),"") -> -0.14985192 | O9: =IFERROR((VLOOKUP($A9,'Dados StatusInvest'!$A:$AZ,COLUMN(O9)-$A$5,0)/VLOOKUP($A9,'Dados StatusInvest'!$A:$AZ,2,0)*$F9),0) -> 103.9373 | P9: =IFERROR((VLOOKUP($A9,'Dados StatusInvest'!$A:$AZ,COLUMN(P9)-$A$5,0)/VLOOKUP($A9,'Dados StatusInvest'!$A:$AZ,2,0)*$F9),0) -> 167.30468 | Q9: =IFERROR((VLOOKUP($A9,'Dados StatusInvest'!$A:$AZ,COLUMN(Q9)-$A$5,0)/100),0) -> 0.6343 | R9: =VLOOKUP($A9,'Dados StatusInvest'!$A:$AZ,COLUMN(R9)-$A$5,0) -> 0.61 | S9: =IFERROR((VLOOKUP($A9,'Dados StatusInvest'!$A:$AZ,COLUMN(S9)-$A$5,0)),0) -> 2.04 | T9: =IFERROR((VLOOKUP($A9,'Dados StatusInvest'!$A:$AZ,COLUMN(T9)-$A$5,0)/VLOOKUP($A9,'Dados StatusInvest'!$A:$AZ,2,0)*$F9),0) -> 5.1149457 | U9: =IFERROR((VLOOKUP($A9,'Dados StatusInvest'!$A:$AZ,COLUMN(U9)-$A$5,0)-VLOOKUP($A9,'Dados StatusInvest'!$A:$AZ,COLUMN(U9)-$A$5-1,0)+T9),0) -> -0.78505429 | V9: =IFERROR((VLOOKUP($A9,'Dados StatusInvest'!$A:$AZ,COLUMN(V9)-$A$5,0)),0) -> 1.61 | W9: =IFERROR((VLOOKUP($A9,'Dados StatusInvest'!$A:$AZ,COLUMN(W9)-$A$5,0)),0) -> -0.08 | X9: =IFERROR((VLOOKUP($A9,'Dados StatusInvest'!$A:$AZ,COLUMN(X9)-$A$5,0)/VLOOKUP($A9,'Dados StatusInvest'!$A:$AZ,2,0)*$F9),0) -> -0.039960513 | Y9: =IFERROR((VLOOKUP($A9,'Dados StatusInvest'!$A:$AZ,COLUMN(Y9)-$A$5,0)/VLOOKUP($A9,'Dados StatusInvest'!$A:$AZ,2,0)*$F9),0) -> -1.0289832 | Z9: =IFERROR((VLOOKUP($A9,'Dados StatusInvest'!$A:$AZ,COLUMN(Z9)-$A$5,0)),0) -> 0.56 | AA9: =IFERROR((VLOOKUP($A9,'Dados StatusInvest'!$A:$AZ,COLUMN(AA9)-$A$5,0)),0) -> 0.44 | AB9: =IFERROR((VLOOKUP($A9,'Dados StatusInvest'!$A:$AZ,COLUMN(AB9)-$A$5,0)),0) -> 0.27 | AC9: =IFERROR((VLOOKUP($A9,'Dados StatusInvest'!$A:$AZ,COLUMN(AC9)-$A$5,0)),0) -> 10.7 | AD9: =IFERROR((VLOOKUP($A9,'Dados StatusInvest'!$A:$AZ,COLUMN(AD9)-$A$5,0)),0) -> 0 | AE9: =IFERROR((VLOOKUP($A9,'Dados StatusInvest'!$A:$AZ,COLUMN(AE9)-$A$5,0)),0) -> 4102180 | AF9: =IFERROR((VLOOKUP($A9,'Dados StatusInvest'!$A:$AZ,COLUMN(AF9)-$A$5,0)),0) -> 20.24 | AG9: =IFERROR((VLOOKUP($A9,'Dados StatusInvest'!$A:$AZ,COLUMN(AG9)-$A$5,0)),0) -> -0.02 | ... AJ9: =IFERROR((VLOOKUP($A9,'Dados StatusInvest'!$A:$AZ,COLUMN(AJ9)-$A$5,0)),0) | AK9: =IFERROR(__xludf.DUMMYFUNCTION("IFERROR(GOOGLEFINANCE($A9,""high""),"""")"),20.26) -> 20.26 | AL9: =IFERROR(__xludf.DUMMYFUNCTION("IFERROR(GOOGLEFINANCE($A9,""low""),"""")"),20.12) -> 20.12 | AM9: =IFERROR(((AK9-AL9)/AL9),0) -> 0.0069582505 | AN9: =IFERROR(__xludf.DUMMYFUNCTION("IFERROR((GOOGLEFINANCE($A9,""volume"")),0)"),8400.0) -> 8400 | AO9: =IFERROR(__xludf.DUMMYFUNCTION("IFERROR((GOOGLEFINANCE($A9,""closeyest"")),"""")"),20.26) -> 20.26 | AP9: =IFERROR(__xludf.DUMMYFUNCTION("IFERROR((GOOGLEFINANCE($A9,""shares"")),"""")"),1.02683444E8) -> 102683444
A10: ='Dados StatusInvest'!A5:A624 -> AGXY3 | B10: =IFERROR(__xludf.DUMMYFUNCTION("IFERROR((GOOGLEFINANCE(A10,""name"")),"""")"),"Agrogalaxy Participacoes SA em Recupera") -> Agrogalaxy Participacoes SA em Recupera | C10: =IFERROR((VLOOKUP(LEFT($A10,4),Setor!$A:$E,3,0)),"") | D10: =IFERROR((VLOOKUP(LEFT($A10,4),Setor!$A:$E,4,0)),"") | E10: =IFERROR((VLOOKUP(LEFT($A10,4),Setor!$A:$E,5,0)),"") | F10: =IFERROR(__xludf.DUMMYFUNCTION("IFERROR((GOOGLEFINANCE(A10)),"""")"),2.45) -> 2.45 | G10: =IFERROR(__xludf.DUMMYFUNCTION("IFERROR((sparkline(GOOGLEFINANCE($A10,""price"",TODAY()-30,TODAY(),""DAILY""),{""charttype"",""line"";""linewidth"",1;""color"",""#5f88cc""})),"""")"),"") | H10: =IFERROR(__xludf.DUMMYFUNCTION("IFERROR((((GOOGLEFINANCE(A10))-(INDEX(GoogleFinance(A10,""PRICE"",$AQ$1),2,2)))/(INDEX(GoogleFinance(A10,""PRICE"",$AQ$1),2,2))),"""")"),-0.38442211055276376) -> -0.38442211 | I10: =IFERROR(__xludf.DUMMYFUNCTION("IFERROR((GOOGLEFINANCE($A10,""high52"")),"""")"),9.9) -> 9.9 | J10: =IFERROR(__xludf.DUMMYFUNCTION("IFERROR((sparkline(GOOGLEFINANCE($A10,""price"",TODAY()-365,TODAY(),""DAILY""),{""charttype"",""line"";""linewidth"",1;""color"",""#5f88cc""})),"""")"),"") | K10: =IFERROR(__xludf.DUMMYFUNCTION("IFERROR((((GOOGLEFINANCE(A10))-(INDEX(GoogleFinance(A10,""PRICE"",$AP$1),2,2)))/(INDEX(GoogleFinance(A10,""PRICE"",$AP$1),2,2))),"""")"),-0.7447916666666666) -> -0.74479167 | L10: =IFERROR(((F10-I10)/I10),0) -> -0.75252525 | M10: =IFERROR((VLOOKUP($A10,'Dados StatusInvest'!$A:$AZ,COLUMN(M10)-$A$5,0)*VLOOKUP($A10,'Dados StatusInvest'!$A:$AZ,2,0)/$F10/100),0) -> 0.40713224 | N10: =IFERROR((VLOOKUP($A10,'Dados StatusInvest'!$A:$AZ,COLUMN(N10)-$A$5,0)/VLOOKUP($A10,'Dados StatusInvest'!$A:$AZ,2,0)*$F10),"") -> 68.385259 | O10: =IFERROR((VLOOKUP($A10,'Dados StatusInvest'!$A:$AZ,COLUMN(O10)-$A$5,0)/VLOOKUP($A10,'Dados StatusInvest'!$A:$AZ,2,0)*$F10),0) -> 0.058565737 | P10: =IFERROR((VLOOKUP($A10,'Dados StatusInvest'!$A:$AZ,COLUMN(P10)-$A$5,0)/VLOOKUP($A10,'Dados StatusInvest'!$A:$AZ,2,0)*$F10),0) -> 1.3860558 | Q10: =IFERROR((VLOOKUP($A10,'Dados StatusInvest'!$A:$AZ,COLUMN(Q10)-$A$5,0)/100),0) -> 0.0136 | R10: =VLOOKUP($A10,'Dados StatusInvest'!$A:$AZ,COLUMN(R10)-$A$5,0) -> 0 | S10: =IFERROR((VLOOKUP($A10,'Dados StatusInvest'!$A:$AZ,COLUMN(S10)-$A$5,0)),0) -> 0.02 | T10: =IFERROR((VLOOKUP($A10,'Dados StatusInvest'!$A:$AZ,COLUMN(T10)-$A$5,0)/VLOOKUP($A10,'Dados StatusInvest'!$A:$AZ,2,0)*$F10),0) -> 0.087848606 | U10: =IFERROR((VLOOKUP($A10,'Dados StatusInvest'!$A:$AZ,COLUMN(U10)-$A$5,0)-VLOOKUP($A10,'Dados StatusInvest'!$A:$AZ,COLUMN(U10)-$A$5-1,0)+T10),0) -> -0.032151394 | V10: =IFERROR((VLOOKUP($A10,'Dados StatusInvest'!$A:$AZ,COLUMN(V10)-$A$5,0)),0) -> 2.19 | W10: =IFERROR((VLOOKUP($A10,'Dados StatusInvest'!$A:$AZ,COLUMN(W10)-$A$5,0)),0) -> -661.54 | X10: =IFERROR((VLOOKUP($A10,'Dados StatusInvest'!$A:$AZ,COLUMN(X10)-$A$5,0)/VLOOKUP($A10,'Dados StatusInvest'!$A:$AZ,2,0)*$F10),0) -> 54.056175 | Y10: =IFERROR((VLOOKUP($A10,'Dados StatusInvest'!$A:$AZ,COLUMN(Y10)-$A$5,0)/VLOOKUP($A10,'Dados StatusInvest'!$A:$AZ,2,0)*$F10),0) -> 81.660159 | Z10: =IFERROR((VLOOKUP($A10,'Dados StatusInvest'!$A:$AZ,COLUMN(Z10)-$A$5,0)),0) -> -0.08 | AA10: =IFERROR((VLOOKUP($A10,'Dados StatusInvest'!$A:$AZ,COLUMN(AA10)-$A$5,0)),0) -> 1.08 | AB10: =IFERROR((VLOOKUP($A10,'Dados StatusInvest'!$A:$AZ,COLUMN(AB10)-$A$5,0)),0) -> 0.79 | AC10: =IFERROR((VLOOKUP($A10,'Dados StatusInvest'!$A:$AZ,COLUMN(AC10)-$A$5,0)),0) -> 24.29 | AD10: =IFERROR((VLOOKUP($A10,'Dados StatusInvest'!$A:$AZ,COLUMN(AD10)-$A$5,0)),0) -> 123.15 | AE10: =IFERROR((VLOOKUP($A10,'Dados StatusInvest'!$A:$AZ,COLUMN(AE10)-$A$5,0)),0) -> 118357.5 | AF10: =IFERROR((VLOOKUP($A10,'Dados StatusInvest'!$A:$AZ,COLUMN(AF10)-$A$5,0)),0) -> -10.93 | AG10: =IFERROR((VLOOKUP($A10,'Dados StatusInvest'!$A:$AZ,COLUMN(AG10)-$A$5,0)),0) -> 72.3 | ... AJ10: =IFERROR((VLOOKUP($A10,'Dados StatusInvest'!$A:$AZ,COLUMN(AJ10)-$A$5,0)),0) | AK10: =IFERROR(__xludf.DUMMYFUNCTION("IFERROR(GOOGLEFINANCE($A10,""high""),"""")"),2.51) -> 2.51 | AL10: =IFERROR(__xludf.DUMMYFUNCTION("IFERROR(GOOGLEFINANCE($A10,""low""),"""")"),2.43) -> 2.43 | AM10: =IFERROR(((AK10-AL10)/AL10),0) -> 0.032921811 | AN10: =IFERROR(__xludf.DUMMYFUNCTION("IFERROR((GOOGLEFINANCE($A10,""volume"")),0)"),10300.0) -> 10300 | AO10: =IFERROR(__xludf.DUMMYFUNCTION("IFERROR((GOOGLEFINANCE($A10,""closeyest"")),"""")"),2.51) -> 2.51 | AP10: =IFERROR(__xludf.DUMMYFUNCTION("IFERROR((GOOGLEFINANCE($A10,""shares"")),"""")"),1.6969571E7) -> 16969571
A11: ='Dados StatusInvest'!A6:A625 -> AHEB3 | B11: =IFERROR(__xludf.DUMMYFUNCTION("IFERROR((GOOGLEFINANCE(A11,""name"")),"""")"),"Sao Paulo Turismo SA") -> Sao Paulo Turismo SA | C11: =IFERROR((VLOOKUP(LEFT($A11,4),Setor!$A:$E,3,0)),"") -> Consumo Cíclico | D11: =IFERROR((VLOOKUP(LEFT($A11,4),Setor!$A:$E,4,0)),"") -> Viagens e Lazer | E11: =IFERROR((VLOOKUP(LEFT($A11,4),Setor!$A:$E,5,0)),"") -> Produção de Eventos e Shows | F11: =IFERROR(__xludf.DUMMYFUNCTION("IFERROR((GOOGLEFINANCE(A11)),"""")"),25.0) -> 25 | G11: =IFERROR(__xludf.DUMMYFUNCTION("IFERROR((sparkline(GOOGLEFINANCE($A11,""price"",TODAY()-30,TODAY(),""DAILY""),{""charttype"",""line"";""linewidth"",1;""color"",""#5f88cc""})),"""")"),"") | H11: =IFERROR(__xludf.DUMMYFUNCTION("IFERROR((((GOOGLEFINANCE(A11))-(INDEX(GoogleFinance(A11,""PRICE"",$AQ$1),2,2)))/(INDEX(GoogleFinance(A11,""PRICE"",$AQ$1),2,2))),"""")"),0.041666666666666664) -> 0.041666667 | I11: =IFERROR(__xludf.DUMMYFUNCTION("IFERROR((GOOGLEFINANCE($A11,""high52"")),"""")"),45.0) -> 45 | J11: =IFERROR(__xludf.DUMMYFUNCTION("IFERROR((sparkline(GOOGLEFINANCE($A11,""price"",TODAY()-365,TODAY(),""DAILY""),{""charttype"",""line"";""linewidth"",1;""color"",""#5f88cc""})),"""")"),"") | K11: =IFERROR(__xludf.DUMMYFUNCTION("IFERROR((((GOOGLEFINANCE(A11))-(INDEX(GoogleFinance(A11,""PRICE"",$AP$1),2,2)))/(INDEX(GoogleFinance(A11,""PRICE"",$AP$1),2,2))),"""")"),"") | L11: =IFERROR(((F11-I11)/I11),0) -> -0.44444444 | M11: =IFERROR((VLOOKUP($A11,'Dados StatusInvest'!$A:$AZ,COLUMN(M11)-$A$5,0)*VLOOKUP($A11,'Dados StatusInvest'!$A:$AZ,2,0)/$F11/100),0) -> 0.1104 | N11: =IFERROR((VLOOKUP($A11,'Dados StatusInvest'!$A:$AZ,COLUMN(N11)-$A$5,0)/VLOOKUP($A11,'Dados StatusInvest'!$A:$AZ,2,0)*$F11),"") -> 12.25 | O11: =IFERROR((VLOOKUP($A11,'Dados StatusInvest'!$A:$AZ,COLUMN(O11)-$A$5,0)/VLOOKUP($A11,'Dados StatusInvest'!$A:$AZ,2,0)*$F11),0) -> 2.87 | P11: =IFERROR((VLOOKUP($A11,'Dados StatusInvest'!$A:$AZ,COLUMN(P11)-$A$5,0)/VLOOKUP($A11,'Dados StatusInvest'!$A:$AZ,2,0)*$F11),0) -> 1.9 | Q11: =IFERROR((VLOOKUP($A11,'Dados StatusInvest'!$A:$AZ,COLUMN(Q11)-$A$5,0)/100),0) -> -0.0103 | R11: =VLOOKUP($A11,'Dados StatusInvest'!$A:$AZ,COLUMN(R11)-$A$5,0) -> -0.3 | S11: =IFERROR((VLOOKUP($A11,'Dados StatusInvest'!$A:$AZ,COLUMN(S11)-$A$5,0)),0) -> 0.32 | T11: =IFERROR((VLOOKUP($A11,'Dados StatusInvest'!$A:$AZ,COLUMN(T11)-$A$5,0)/VLOOKUP($A11,'Dados StatusInvest'!$A:$AZ,2,0)*$F11),0) -> 1.43 | U11: =IFERROR((VLOOKUP($A11,'Dados StatusInvest'!$A:$AZ,COLUMN(U11)-$A$5,0)-VLOOKUP($A11,'Dados StatusInvest'!$A:$AZ,COLUMN(U11)-$A$5-1,0)+T11),0) -> -0.63 | V11: =IFERROR((VLOOKUP($A11,'Dados StatusInvest'!$A:$AZ,COLUMN(V11)-$A$5,0)),0) -> 2.46 | W11: =IFERROR((VLOOKUP($A11,'Dados StatusInvest'!$A:$AZ,COLUMN(W11)-$A$5,0)),0) -> 32.19 | X11: =IFERROR((VLOOKUP($A11,'Dados StatusInvest'!$A:$AZ,COLUMN(X11)-$A$5,0)/VLOOKUP($A11,'Dados StatusInvest'!$A:$AZ,2,0)*$F11),0) -> 13.95 | Y11: =IFERROR((VLOOKUP($A11,'Dados StatusInvest'!$A:$AZ,COLUMN(Y11)-$A$5,0)/VLOOKUP($A11,'Dados StatusInvest'!$A:$AZ,2,0)*$F11),0) -> 27.08 | Z11: =IFERROR((VLOOKUP($A11,'Dados StatusInvest'!$A:$AZ,COLUMN(Z11)-$A$5,0)),0) -> 0.43 | AA11: =IFERROR((VLOOKUP($A11,'Dados StatusInvest'!$A:$AZ,COLUMN(AA11)-$A$5,0)),0) -> 0.57 | AB11: =IFERROR((VLOOKUP($A11,'Dados StatusInvest'!$A:$AZ,COLUMN(AB11)-$A$5,0)),0) -> 1.14 | AC11: =IFERROR((VLOOKUP($A11,'Dados StatusInvest'!$A:$AZ,COLUMN(AC11)-$A$5,0)),0) -> 44.62 | AD11: =IFERROR((VLOOKUP($A11,'Dados StatusInvest'!$A:$AZ,COLUMN(AD11)-$A$5,0)),0) -> 0 | AE11: =IFERROR((VLOOKUP($A11,'Dados StatusInvest'!$A:$AZ,COLUMN(AE11)-$A$5,0)),0) -> 2100 | AF11: =IFERROR((VLOOKUP($A11,'Dados StatusInvest'!$A:$AZ,COLUMN(AF11)-$A$5,0)),0) -> 30 | AG11: =IFERROR((VLOOKUP($A11,'Dados StatusInvest'!$A:$AZ,COLUMN(AG11)-$A$5,0)),0) -> 9.66 | ... AJ11: =IFERROR((VLOOKUP($A11,'Dados StatusInvest'!$A:$AZ,COLUMN(AJ11)-$A$5,0)),0) | AK11: =IFERROR(__xludf.DUMMYFUNCTION("IFERROR(GOOGLEFINANCE($A11,""high""),"""")"),"") | AL11: =IFERROR(__xludf.DUMMYFUNCTION("IFERROR(GOOGLEFINANCE($A11,""low""),"""")"),"") | AM11: =IFERROR(((AK11-AL11)/AL11),0) -> 0 | AN11: =IFERROR(__xludf.DUMMYFUNCTION("IFERROR((GOOGLEFINANCE($A11,""volume"")),0)"),0.0) -> 0 | AO11: =IFERROR(__xludf.DUMMYFUNCTION("IFERROR((GOOGLEFINANCE($A11,""closeyest"")),"""")"),25.0) -> 25 | AP11: =IFERROR(__xludf.DUMMYFUNCTION("IFERROR((GOOGLEFINANCE($A11,""shares"")),"""")"),8407877.0) -> 8407877
A12: ='Dados StatusInvest'!A7:A626 -> AHEB5 | B12: =IFERROR(__xludf.DUMMYFUNCTION("IFERROR((GOOGLEFINANCE(A12,""name"")),"""")"),"Sao Paulo Turismo Class Pref Shs Class A") -> Sao Paulo Turismo Class Pref Shs Class A | C12: =IFERROR((VLOOKUP(LEFT($A12,4),Setor!$A:$E,3,0)),"") -> Consumo Cíclico | D12: =IFERROR((VLOOKUP(LEFT($A12,4),Setor!$A:$E,4,0)),"") -> Viagens e Lazer | E12: =IFERROR((VLOOKUP(LEFT($A12,4),Setor!$A:$E,5,0)),"") -> Produção de Eventos e Shows | F12: =IFERROR(__xludf.DUMMYFUNCTION("IFERROR((GOOGLEFINANCE(A12)),"""")"),58.0) -> 58 | G12: =IFERROR(__xludf.DUMMYFUNCTION("IFERROR((sparkline(GOOGLEFINANCE($A12,""price"",TODAY()-30,TODAY(),""DAILY""),{""charttype"",""line"";""linewidth"",1;""color"",""#5f88cc""})),"""")"),"") | H12: =IFERROR(__xludf.DUMMYFUNCTION("IFERROR((((GOOGLEFINANCE(A12))-(INDEX(GoogleFinance(A12,""PRICE"",$AQ$1),2,2)))/(INDEX(GoogleFinance(A12,""PRICE"",$AQ$1),2,2))),"""")"),"") | I12: =IFERROR(__xludf.DUMMYFUNCTION("IFERROR((GOOGLEFINANCE($A12,""high52"")),"""")"),58.0) -> 58 | J12: =IFERROR(__xludf.DUMMYFUNCTION("IFERROR((sparkline(GOOGLEFINANCE($A12,""price"",TODAY()-365,TODAY(),""DAILY""),{""charttype"",""line"";""linewidth"",1;""color"",""#5f88cc""})),"""")"),"") | K12: =IFERROR(__xludf.DUMMYFUNCTION("IFERROR((((GOOGLEFINANCE(A12))-(INDEX(GoogleFinance(A12,""PRICE"",$AP$1),2,2)))/(INDEX(GoogleFinance(A12,""PRICE"",$AP$1),2,2))),"""")"),"") | L12: =IFERROR(((F12-I12)/I12),0) -> 0 | M12: =IFERROR((VLOOKUP($A12,'Dados StatusInvest'!$A:$AZ,COLUMN(M12)-$A$5,0)*VLOOKUP($A12,'Dados StatusInvest'!$A:$AZ,2,0)/$F12/100),0) -> 0.1104 | N12: =IFERROR((VLOOKUP($A12,'Dados StatusInvest'!$A:$AZ,COLUMN(N12)-$A$5,0)/VLOOKUP($A12,'Dados StatusInvest'!$A:$AZ,2,0)*$F12),"") -> 12.25 | O12: =IFERROR((VLOOKUP($A12,'Dados StatusInvest'!$A:$AZ,COLUMN(O12)-$A$5,0)/VLOOKUP($A12,'Dados StatusInvest'!$A:$AZ,2,0)*$F12),0) -> 6.67 | P12: =IFERROR((VLOOKUP($A12,'Dados StatusInvest'!$A:$AZ,COLUMN(P12)-$A$5,0)/VLOOKUP($A12,'Dados StatusInvest'!$A:$AZ,2,0)*$F12),0) -> 1.9 | Q12: =IFERROR((VLOOKUP($A12,'Dados StatusInvest'!$A:$AZ,COLUMN(Q12)-$A$5,0)/100),0) -> -0.0103 | R12: =VLOOKUP($A12,'Dados StatusInvest'!$A:$AZ,COLUMN(R12)-$A$5,0) -> -0.3 | S12: =IFERROR((VLOOKUP($A12,'Dados StatusInvest'!$A:$AZ,COLUMN(S12)-$A$5,0)),0) -> 0.74 | T12: =IFERROR((VLOOKUP($A12,'Dados StatusInvest'!$A:$AZ,COLUMN(T12)-$A$5,0)/VLOOKUP($A12,'Dados StatusInvest'!$A:$AZ,2,0)*$F12),0) -> 3.33 | U12: =IFERROR((VLOOKUP($A12,'Dados StatusInvest'!$A:$AZ,COLUMN(U12)-$A$5,0)-VLOOKUP($A12,'Dados StatusInvest'!$A:$AZ,COLUMN(U12)-$A$5-1,0)+T12),0) -> -1.45 | V12: =IFERROR((VLOOKUP($A12,'Dados StatusInvest'!$A:$AZ,COLUMN(V12)-$A$5,0)),0) -> 2.46 | W12: =IFERROR((VLOOKUP($A12,'Dados StatusInvest'!$A:$AZ,COLUMN(W12)-$A$5,0)),0) -> 32.19 | X12: =IFERROR((VLOOKUP($A12,'Dados StatusInvest'!$A:$AZ,COLUMN(X12)-$A$5,0)/VLOOKUP($A12,'Dados StatusInvest'!$A:$AZ,2,0)*$F12),0) -> 13.95 | Y12: =IFERROR((VLOOKUP($A12,'Dados StatusInvest'!$A:$AZ,COLUMN(Y12)-$A$5,0)/VLOOKUP($A12,'Dados StatusInvest'!$A:$AZ,2,0)*$F12),0) -> 27.08 | Z12: =IFERROR((VLOOKUP($A12,'Dados StatusInvest'!$A:$AZ,COLUMN(Z12)-$A$5,0)),0) -> 0.43 | AA12: =IFERROR((VLOOKUP($A12,'Dados StatusInvest'!$A:$AZ,COLUMN(AA12)-$A$5,0)),0) -> 0.57 | AB12: =IFERROR((VLOOKUP($A12,'Dados StatusInvest'!$A:$AZ,COLUMN(AB12)-$A$5,0)),0) -> 1.14 | AC12: =IFERROR((VLOOKUP($A12,'Dados StatusInvest'!$A:$AZ,COLUMN(AC12)-$A$5,0)),0) -> 44.62 | AD12: =IFERROR((VLOOKUP($A12,'Dados StatusInvest'!$A:$AZ,COLUMN(AD12)-$A$5,0)),0) -> 0 | AE12: =IFERROR((VLOOKUP($A12,'Dados StatusInvest'!$A:$AZ,COLUMN(AE12)-$A$5,0)),0) -> 0 | AF12: =IFERROR((VLOOKUP($A12,'Dados StatusInvest'!$A:$AZ,COLUMN(AF12)-$A$5,0)),0) -> 30 | AG12: =IFERROR((VLOOKUP($A12,'Dados StatusInvest'!$A:$AZ,COLUMN(AG12)-$A$5,0)),0) -> 9.66 | ... AJ12: =IFERROR((VLOOKUP($A12,'Dados StatusInvest'!$A:$AZ,COLUMN(AJ12)-$A$5,0)),0) | AK12: =IFERROR(__xludf.DUMMYFUNCTION("IFERROR(GOOGLEFINANCE($A12,""high""),"""")"),"") | AL12: =IFERROR(__xludf.DUMMYFUNCTION("IFERROR(GOOGLEFINANCE($A12,""low""),"""")"),"") | AM12: =IFERROR(((AK12-AL12)/AL12),0) -> 0 | AN12: =IFERROR(__xludf.DUMMYFUNCTION("IFERROR((GOOGLEFINANCE($A12,""volume"")),0)"),0.0) -> 0 | AO12: =IFERROR(__xludf.DUMMYFUNCTION("IFERROR((GOOGLEFINANCE($A12,""closeyest"")),"""")"),58.0) -> 58 | AP12: =IFERROR(__xludf.DUMMYFUNCTION("IFERROR((GOOGLEFINANCE($A12,""shares"")),"""")"),45022.0) -> 45022
A13: ='Dados StatusInvest'!A8:A627 -> AHEB6 | B13: =IFERROR(__xludf.DUMMYFUNCTION("IFERROR((GOOGLEFINANCE(A13,""name"")),"""")"),"Sao Paulo Turismo Class Pref Shs Class B") -> Sao Paulo Turismo Class Pref Shs Class B | C13: =IFERROR((VLOOKUP(LEFT($A13,4),Setor!$A:$E,3,0)),"") -> Consumo Cíclico | D13: =IFERROR((VLOOKUP(LEFT($A13,4),Setor!$A:$E,4,0)),"") -> Viagens e Lazer | E13: =IFERROR((VLOOKUP(LEFT($A13,4),Setor!$A:$E,5,0)),"") -> Produção de Eventos e Shows | F13: =IFERROR(__xludf.DUMMYFUNCTION("IFERROR((GOOGLEFINANCE(A13)),"""")"),55.0) -> 55 | G13: =IFERROR(__xludf.DUMMYFUNCTION("IFERROR((sparkline(GOOGLEFINANCE($A13,""price"",TODAY()-30,TODAY(),""DAILY""),{""charttype"",""line"";""linewidth"",1;""color"",""#5f88cc""})),"""")"),"") | H13: =IFERROR(__xludf.DUMMYFUNCTION("IFERROR((((GOOGLEFINANCE(A13))-(INDEX(GoogleFinance(A13,""PRICE"",$AQ$1),2,2)))/(INDEX(GoogleFinance(A13,""PRICE"",$AQ$1),2,2))),"""")"),"") | I13: =IFERROR(__xludf.DUMMYFUNCTION("IFERROR((GOOGLEFINANCE($A13,""high52"")),"""")"),55.0) -> 55 | J13: =IFERROR(__xludf.DUMMYFUNCTION("IFERROR((sparkline(GOOGLEFINANCE($A13,""price"",TODAY()-365,TODAY(),""DAILY""),{""charttype"",""line"";""linewidth"",1;""color"",""#5f88cc""})),"""")"),"") | K13: =IFERROR(__xludf.DUMMYFUNCTION("IFERROR((((GOOGLEFINANCE(A13))-(INDEX(GoogleFinance(A13,""PRICE"",$AP$1),2,2)))/(INDEX(GoogleFinance(A13,""PRICE"",$AP$1),2,2))),"""")"),"") | L13: =IFERROR(((F13-I13)/I13),0) -> 0 | M13: =IFERROR((VLOOKUP($A13,'Dados StatusInvest'!$A:$AZ,COLUMN(M13)-$A$5,0)*VLOOKUP($A13,'Dados StatusInvest'!$A:$AZ,2,0)/$F13/100),0) -> 0.1104 | N13: =IFERROR((VLOOKUP($A13,'Dados StatusInvest'!$A:$AZ,COLUMN(N13)-$A$5,0)/VLOOKUP($A13,'Dados StatusInvest'!$A:$AZ,2,0)*$F13),"") -> 12.25 | O13: =IFERROR((VLOOKUP($A13,'Dados StatusInvest'!$A:$AZ,COLUMN(O13)-$A$5,0)/VLOOKUP($A13,'Dados StatusInvest'!$A:$AZ,2,0)*$F13),0) -> 6.32 | P13: =IFERROR((VLOOKUP($A13,'Dados StatusInvest'!$A:$AZ,COLUMN(P13)-$A$5,0)/VLOOKUP($A13,'Dados StatusInvest'!$A:$AZ,2,0)*$F13),0) -> 1.9 | Q13: =IFERROR((VLOOKUP($A13,'Dados StatusInvest'!$A:$AZ,COLUMN(Q13)-$A$5,0)/100),0) -> -0.0103 | R13: =VLOOKUP($A13,'Dados StatusInvest'!$A:$AZ,COLUMN(R13)-$A$5,0) -> -0.3 | S13: =IFERROR((VLOOKUP($A13,'Dados StatusInvest'!$A:$AZ,COLUMN(S13)-$A$5,0)),0) -> 0.7 | T13: =IFERROR((VLOOKUP($A13,'Dados StatusInvest'!$A:$AZ,COLUMN(T13)-$A$5,0)/VLOOKUP($A13,'Dados StatusInvest'!$A:$AZ,2,0)*$F13),0) -> 3.15 | U13: =IFERROR((VLOOKUP($A13,'Dados StatusInvest'!$A:$AZ,COLUMN(U13)-$A$5,0)-VLOOKUP($A13,'Dados StatusInvest'!$A:$AZ,COLUMN(U13)-$A$5-1,0)+T13),0) -> -1.38 | V13: =IFERROR((VLOOKUP($A13,'Dados StatusInvest'!$A:$AZ,COLUMN(V13)-$A$5,0)),0) -> 2.46 | W13: =IFERROR((VLOOKUP($A13,'Dados StatusInvest'!$A:$AZ,COLUMN(W13)-$A$5,0)),0) -> 32.19 | X13: =IFERROR((VLOOKUP($A13,'Dados StatusInvest'!$A:$AZ,COLUMN(X13)-$A$5,0)/VLOOKUP($A13,'Dados StatusInvest'!$A:$AZ,2,0)*$F13),0) -> 13.95 | Y13: =IFERROR((VLOOKUP($A13,'Dados StatusInvest'!$A:$AZ,COLUMN(Y13)-$A$5,0)/VLOOKUP($A13,'Dados StatusInvest'!$A:$AZ,2,0)*$F13),0) -> 27.08 | Z13: =IFERROR((VLOOKUP($A13,'Dados StatusInvest'!$A:$AZ,COLUMN(Z13)-$A$5,0)),0) -> 0.43 | AA13: =IFERROR((VLOOKUP($A13,'Dados StatusInvest'!$A:$AZ,COLUMN(AA13)-$A$5,0)),0) -> 0.57 | AB13: =IFERROR((VLOOKUP($A13,'Dados StatusInvest'!$A:$AZ,COLUMN(AB13)-$A$5,0)),0) -> 1.14 | AC13: =IFERROR((VLOOKUP($A13,'Dados StatusInvest'!$A:$AZ,COLUMN(AC13)-$A$5,0)),0) -> 44.62 | AD13: =IFERROR((VLOOKUP($A13,'Dados StatusInvest'!$A:$AZ,COLUMN(AD13)-$A$5,0)),0) -> 0 | AE13: =IFERROR((VLOOKUP($A13,'Dados StatusInvest'!$A:$AZ,COLUMN(AE13)-$A$5,0)),0) -> 5500 | AF13: =IFERROR((VLOOKUP($A13,'Dados StatusInvest'!$A:$AZ,COLUMN(AF13)-$A$5,0)),0) -> 30 | AG13: =IFERROR((VLOOKUP($A13,'Dados StatusInvest'!$A:$AZ,COLUMN(AG13)-$A$5,0)),0) -> 9.66 | ... AJ13: =IFERROR((VLOOKUP($A13,'Dados StatusInvest'!$A:$AZ,COLUMN(AJ13)-$A$5,0)),0) | AK13: =IFERROR(__xludf.DUMMYFUNCTION("IFERROR(GOOGLEFINANCE($A13,""high""),"""")"),"") | AL13: =IFERROR(__xludf.DUMMYFUNCTION("IFERROR(GOOGLEFINANCE($A13,""low""),"""")"),"") | AM13: =IFERROR(((AK13-AL13)/AL13),0) -> 0 | AN13: =IFERROR(__xludf.DUMMYFUNCTION("IFERROR((GOOGLEFINANCE($A13,""volume"")),0)"),0.0) -> 0 | AO13: =IFERROR(__xludf.DUMMYFUNCTION("IFERROR((GOOGLEFINANCE($A13,""closeyest"")),"""")"),55.0) -> 55 | AP13: =IFERROR(__xludf.DUMMYFUNCTION("IFERROR((GOOGLEFINANCE($A13,""shares"")),"""")"),90995.0) -> 90995
A14: ='Dados StatusInvest'!A9:A628 -> ALLD3 | B14: =IFERROR(__xludf.DUMMYFUNCTION("IFERROR((GOOGLEFINANCE(A14,""name"")),"""")"),"Allied Tecnologia SA") -> Allied Tecnologia SA | C14: =IFERROR((VLOOKUP(LEFT($A14,4),Setor!$A:$E,3,0)),"") | D14: =IFERROR((VLOOKUP(LEFT($A14,4),Setor!$A:$E,4,0)),"") | E14: =IFERROR((VLOOKUP(LEFT($A14,4),Setor!$A:$E,5,0)),"") | F14: =IFERROR(__xludf.DUMMYFUNCTION("IFERROR((GOOGLEFINANCE(A14)),"""")"),7.48) -> 7.48 | G14: =IFERROR(__xludf.DUMMYFUNCTION("IFERROR((sparkline(GOOGLEFINANCE($A14,""price"",TODAY()-30,TODAY(),""DAILY""),{""charttype"",""line"";""linewidth"",1;""color"",""#5f88cc""})),"""")"),"") | H14: =IFERROR(__xludf.DUMMYFUNCTION("IFERROR((((GOOGLEFINANCE(A14))-(INDEX(GoogleFinance(A14,""PRICE"",$AQ$1),2,2)))/(INDEX(GoogleFinance(A14,""PRICE"",$AQ$1),2,2))),"""")"),-0.11269276393831545) -> -0.11269276 | I14: =IFERROR(__xludf.DUMMYFUNCTION("IFERROR((GOOGLEFINANCE($A14,""high52"")),"""")"),8.23) -> 8.23 | J14: =IFERROR(__xludf.DUMMYFUNCTION("IFERROR((sparkline(GOOGLEFINANCE($A14,""price"",TODAY()-365,TODAY(),""DAILY""),{""charttype"",""line"";""linewidth"",1;""color"",""#5f88cc""})),"""")"),"") | K14: =IFERROR(__xludf.DUMMYFUNCTION("IFERROR((((GOOGLEFINANCE(A14))-(INDEX(GoogleFinance(A14,""PRICE"",$AP$1),2,2)))/(INDEX(GoogleFinance(A14,""PRICE"",$AP$1),2,2))),"""")"),0.056497175141242986) -> 0.056497175 | L14: =IFERROR(((F14-I14)/I14),0) -> -0.091130012 | M14: =IFERROR((VLOOKUP($A14,'Dados StatusInvest'!$A:$AZ,COLUMN(M14)-$A$5,0)*VLOOKUP($A14,'Dados StatusInvest'!$A:$AZ,2,0)/$F14/100),0) -> 0.093396791 | N14: =IFERROR((VLOOKUP($A14,'Dados StatusInvest'!$A:$AZ,COLUMN(N14)-$A$5,0)/VLOOKUP($A14,'Dados StatusInvest'!$A:$AZ,2,0)*$F14),"") -> 6.5151596 | O14: =IFERROR((VLOOKUP($A14,'Dados StatusInvest'!$A:$AZ,COLUMN(O14)-$A$5,0)/VLOOKUP($A14,'Dados StatusInvest'!$A:$AZ,2,0)*$F14),0) -> 1.4323404 | P14: =IFERROR((VLOOKUP($A14,'Dados StatusInvest'!$A:$AZ,COLUMN(P14)-$A$5,0)/VLOOKUP($A14,'Dados StatusInvest'!$A:$AZ,2,0)*$F14),0) -> 1.1140426 | Q14: =IFERROR((VLOOKUP($A14,'Dados StatusInvest'!$A:$AZ,COLUMN(Q14)-$A$5,0)/100),0) -> -0.0032 | R14: =VLOOKUP($A14,'Dados StatusInvest'!$A:$AZ,COLUMN(R14)-$A$5,0) -> -0.09 | S14: =IFERROR((VLOOKUP($A14,'Dados StatusInvest'!$A:$AZ,COLUMN(S14)-$A$5,0)),0) -> 0.13 | T14: =IFERROR((VLOOKUP($A14,'Dados StatusInvest'!$A:$AZ,COLUMN(T14)-$A$5,0)/VLOOKUP($A14,'Dados StatusInvest'!$A:$AZ,2,0)*$F14),0) -> 0.56696809 | U14: =IFERROR((VLOOKUP($A14,'Dados StatusInvest'!$A:$AZ,COLUMN(U14)-$A$5,0)-VLOOKUP($A14,'Dados StatusInvest'!$A:$AZ,COLUMN(U14)-$A$5-1,0)+T14),0) -> -0.74303191 | V14: =IFERROR((VLOOKUP($A14,'Dados StatusInvest'!$A:$AZ,COLUMN(V14)-$A$5,0)),0) -> 1.81 | W14: =IFERROR((VLOOKUP($A14,'Dados StatusInvest'!$A:$AZ,COLUMN(W14)-$A$5,0)),0) -> 20.88 | X14: =IFERROR((VLOOKUP($A14,'Dados StatusInvest'!$A:$AZ,COLUMN(X14)-$A$5,0)/VLOOKUP($A14,'Dados StatusInvest'!$A:$AZ,2,0)*$F14),0) -> 9.3102128 | Y14: =IFERROR((VLOOKUP($A14,'Dados StatusInvest'!$A:$AZ,COLUMN(Y14)-$A$5,0)/VLOOKUP($A14,'Dados StatusInvest'!$A:$AZ,2,0)*$F14),0) -> 17.088617 | Z14: =IFERROR((VLOOKUP($A14,'Dados StatusInvest'!$A:$AZ,COLUMN(Z14)-$A$5,0)),0) -> 0.45 | AA14: =IFERROR((VLOOKUP($A14,'Dados StatusInvest'!$A:$AZ,COLUMN(AA14)-$A$5,0)),0) -> 0.55 | AB14: =IFERROR((VLOOKUP($A14,'Dados StatusInvest'!$A:$AZ,COLUMN(AB14)-$A$5,0)),0) -> 1.43 | AC14: =IFERROR((VLOOKUP($A14,'Dados StatusInvest'!$A:$AZ,COLUMN(AC14)-$A$5,0)),0) -> 8.27 | AD14: =IFERROR((VLOOKUP($A14,'Dados StatusInvest'!$A:$AZ,COLUMN(AD14)-$A$5,0)),0) -> 28.55 | AE14: =IFERROR((VLOOKUP($A14,'Dados StatusInvest'!$A:$AZ,COLUMN(AE14)-$A$5,0)),0) -> 5234240 | AF14: =IFERROR((VLOOKUP($A14,'Dados StatusInvest'!$A:$AZ,COLUMN(AF14)-$A$5,0)),0) -> 17.68 | AG14: =IFERROR((VLOOKUP($A14,'Dados StatusInvest'!$A:$AZ,COLUMN(AG14)-$A$5,0)),0) -> 3.69 | ... AJ14: =IFERROR((VLOOKUP($A14,'Dados StatusInvest'!$A:$AZ,COLUMN(AJ14)-$A$5,0)),0) | AK14: =IFERROR(__xludf.DUMMYFUNCTION("IFERROR(GOOGLEFINANCE($A14,""high""),"""")"),7.51) -> 7.51 | AL14: =IFERROR(__xludf.DUMMYFUNCTION("IFERROR(GOOGLEFINANCE($A14,""low""),"""")"),7.45) -> 7.45 | AM14: =IFERROR(((AK14-AL14)/AL14),0) -> 0.0080536913 | AN14: =IFERROR(__xludf.DUMMYFUNCTION("IFERROR((GOOGLEFINANCE($A14,""volume"")),0)"),19900.0) -> 19900 | AO14: =IFERROR(__xludf.DUMMYFUNCTION("IFERROR((GOOGLEFINANCE($A14,""closeyest"")),"""")"),7.52) -> 7.52 | AP14: =IFERROR(__xludf.DUMMYFUNCTION("IFERROR((GOOGLEFINANCE($A14,""shares"")),"""")"),9.5690787E7) -> 95690787
A15: ='Dados StatusInvest'!A10:A629 -> ALOS3 | B15: =IFERROR(__xludf.DUMMYFUNCTION("IFERROR((GOOGLEFINANCE(A15,""name"")),"""")"),"Allos SA") -> Allos SA | C15: =IFERROR((VLOOKUP(LEFT($A15,4),Setor!$A:$E,3,0)),"") -> Outros | D15: =IFERROR((VLOOKUP(LEFT($A15,4),Setor!$A:$E,4,0)),"") -> Comércio | E15: =IFERROR((VLOOKUP(LEFT($A15,4),Setor!$A:$E,5,0)),"") -> Comércio | F15: =IFERROR(__xludf.DUMMYFUNCTION("IFERROR((GOOGLEFINANCE(A15)),"""")"),31.13) -> 31.13 | G15: =IFERROR(__xludf.DUMMYFUNCTION("IFERROR((sparkline(GOOGLEFINANCE($A15,""price"",TODAY()-30,TODAY(),""DAILY""),{""charttype"",""line"";""linewidth"",1;""color"",""#5f88cc""})),"""")"),"") | H15: =IFERROR(__xludf.DUMMYFUNCTION("IFERROR((((GOOGLEFINANCE(A15))-(INDEX(GoogleFinance(A15,""PRICE"",$AQ$1),2,2)))/(INDEX(GoogleFinance(A15,""PRICE"",$AQ$1),2,2))),"""")"),0.06829100892244332) -> 0.068291009 | I15: =IFERROR(__xludf.DUMMYFUNCTION("IFERROR((GOOGLEFINANCE($A15,""high52"")),"""")"),31.66) -> 31.66 | J15: =IFERROR(__xludf.DUMMYFUNCTION("IFERROR((sparkline(GOOGLEFINANCE($A15,""price"",TODAY()-365,TODAY(),""DAILY""),{""charttype"",""line"";""linewidth"",1;""color"",""#5f88cc""})),"""")"),"") | K15: =IFERROR(__xludf.DUMMYFUNCTION("IFERROR((((GOOGLEFINANCE(A15))-(INDEX(GoogleFinance(A15,""PRICE"",$AP$1),2,2)))/(INDEX(GoogleFinance(A15,""PRICE"",$AP$1),2,2))),"""")"),0.6230448383733055) -> 0.62304484 | L15: =IFERROR(((F15-I15)/I15),0) -> -0.016740366 | M15: =IFERROR((VLOOKUP($A15,'Dados StatusInvest'!$A:$AZ,COLUMN(M15)-$A$5,0)*VLOOKUP($A15,'Dados StatusInvest'!$A:$AZ,2,0)/$F15/100),0) -> 0.57171539 | N15: =IFERROR((VLOOKUP($A15,'Dados StatusInvest'!$A:$AZ,COLUMN(N15)-$A$5,0)/VLOOKUP($A15,'Dados StatusInvest'!$A:$AZ,2,0)*$F15),"") -> 26.171239 | O15: =IFERROR((VLOOKUP($A15,'Dados StatusInvest'!$A:$AZ,COLUMN(O15)-$A$5,0)/VLOOKUP($A15,'Dados StatusInvest'!$A:$AZ,2,0)*$F15),0) -> 9.8880057 | P15: =IFERROR((VLOOKUP($A15,'Dados StatusInvest'!$A:$AZ,COLUMN(P15)-$A$5,0)/VLOOKUP($A15,'Dados StatusInvest'!$A:$AZ,2,0)*$F15),0) -> 8.0875032 | Q15: =IFERROR((VLOOKUP($A15,'Dados StatusInvest'!$A:$AZ,COLUMN(Q15)-$A$5,0)/100),0) -> -0.0183 | R15: =VLOOKUP($A15,'Dados StatusInvest'!$A:$AZ,COLUMN(R15)-$A$5,0) -> -0.22 | S15: =IFERROR((VLOOKUP($A15,'Dados StatusInvest'!$A:$AZ,COLUMN(S15)-$A$5,0)),0) -> 5.65 | T15: =IFERROR((VLOOKUP($A15,'Dados StatusInvest'!$A:$AZ,COLUMN(T15)-$A$5,0)/VLOOKUP($A15,'Dados StatusInvest'!$A:$AZ,2,0)*$F15),0) -> 6.1492573 | U15: =IFERROR((VLOOKUP($A15,'Dados StatusInvest'!$A:$AZ,COLUMN(U15)-$A$5,0)-VLOOKUP($A15,'Dados StatusInvest'!$A:$AZ,COLUMN(U15)-$A$5-1,0)+T15),0) -> -0.81074273 | V15: =IFERROR((VLOOKUP($A15,'Dados StatusInvest'!$A:$AZ,COLUMN(V15)-$A$5,0)),0) -> 3.06 | W15: =IFERROR((VLOOKUP($A15,'Dados StatusInvest'!$A:$AZ,COLUMN(W15)-$A$5,0)),0) -> 5.59 | X15: =IFERROR((VLOOKUP($A15,'Dados StatusInvest'!$A:$AZ,COLUMN(X15)-$A$5,0)/VLOOKUP($A15,'Dados StatusInvest'!$A:$AZ,2,0)*$F15),0) -> 2.8040613 | Y15: =IFERROR((VLOOKUP($A15,'Dados StatusInvest'!$A:$AZ,COLUMN(Y15)-$A$5,0)/VLOOKUP($A15,'Dados StatusInvest'!$A:$AZ,2,0)*$F15),0) -> 10.478334 | Z15: =IFERROR((VLOOKUP($A15,'Dados StatusInvest'!$A:$AZ,COLUMN(Z15)-$A$5,0)),0) -> 0.51 | AA15: =IFERROR((VLOOKUP($A15,'Dados StatusInvest'!$A:$AZ,COLUMN(AA15)-$A$5,0)),0) -> 0.46 | AB15: =IFERROR((VLOOKUP($A15,'Dados StatusInvest'!$A:$AZ,COLUMN(AB15)-$A$5,0)),0) -> 0.11 | AC15: =IFERROR((VLOOKUP($A15,'Dados StatusInvest'!$A:$AZ,COLUMN(AC15)-$A$5,0)),0) -> 29.82 | AD15: =IFERROR((VLOOKUP($A15,'Dados StatusInvest'!$A:$AZ,COLUMN(AD15)-$A$5,0)),0) -> 102.53 | AE15: =IFERROR((VLOOKUP($A15,'Dados StatusInvest'!$A:$AZ,COLUMN(AE15)-$A$5,0)),0) -> 178000000 | AF15: =IFERROR((VLOOKUP($A15,'Dados StatusInvest'!$A:$AZ,COLUMN(AF15)-$A$5,0)),0) -> 26.62 | AG15: =IFERROR((VLOOKUP($A15,'Dados StatusInvest'!$A:$AZ,COLUMN(AG15)-$A$5,0)),0) -> 1.49 | ... AJ15: =IFERROR((VLOOKUP($A15,'Dados StatusInvest'!$A:$AZ,COLUMN(AJ15)-$A$5,0)),0) | AK15: =IFERROR(__xludf.DUMMYFUNCTION("IFERROR(GOOGLEFINANCE($A15,""high""),"""")"),31.22) -> 31.22 | AL15: =IFERROR(__xludf.DUMMYFUNCTION("IFERROR(GOOGLEFINANCE($A15,""low""),"""")"),30.93) -> 30.93 | AM15: =IFERROR(((AK15-AL15)/AL15),0) -> 0.0093760103 | AN15: =IFERROR(__xludf.DUMMYFUNCTION("IFERROR((GOOGLEFINANCE($A15,""volume"")),0)"),88400.0) -> 88400 | AO15: =IFERROR(__xludf.DUMMYFUNCTION("IFERROR((GOOGLEFINANCE($A15,""closeyest"")),"""")"),31.35) -> 31.35 | AP15: =IFERROR(__xludf.DUMMYFUNCTION("IFERROR((GOOGLEFINANCE($A15,""shares"")),"""")"),5.04190947E8) -> 504190947
A16: ='Dados StatusInvest'!A11:A630 -> ALPA3 | B16: =IFERROR(__xludf.DUMMYFUNCTION("IFERROR((GOOGLEFINANCE(A16,""name"")),"""")"),"Alpargatas SA") -> Alpargatas SA | C16: =IFERROR((VLOOKUP(LEFT($A16,4),Setor!$A:$E,3,0)),"") -> Consumo Cíclico | D16: =IFERROR((VLOOKUP(LEFT($A16,4),Setor!$A:$E,4,0)),"") -> Tecidos, Vestuário e Calçados | E16: =IFERROR((VLOOKUP(LEFT($A16,4),Setor!$A:$E,5,0)),"") -> Calçados | F16: =IFERROR(__xludf.DUMMYFUNCTION("IFERROR((GOOGLEFINANCE(A16)),"""")"),12.35) -> 12.35 | G16: =IFERROR(__xludf.DUMMYFUNCTION("IFERROR((sparkline(GOOGLEFINANCE($A16,""price"",TODAY()-30,TODAY(),""DAILY""),{""charttype"",""line"";""linewidth"",1;""color"",""#5f88cc""})),"""")"),"") | H16: =IFERROR(__xludf.DUMMYFUNCTION("IFERROR((((GOOGLEFINANCE(A16))-(INDEX(GoogleFinance(A16,""PRICE"",$AQ$1),2,2)))/(INDEX(GoogleFinance(A16,""PRICE"",$AQ$1),2,2))),"""")"),0.21915103652517262) -> 0.21915104 | I16: =IFERROR(__xludf.DUMMYFUNCTION("IFERROR((GOOGLEFINANCE($A16,""high52"")),"""")"),13.49) -> 13.49 | J16: =IFERROR(__xludf.DUMMYFUNCTION("IFERROR((sparkline(GOOGLEFINANCE($A16,""price"",TODAY()-365,TODAY(),""DAILY""),{""charttype"",""line"";""linewidth"",1;""color"",""#5f88cc""})),"""")"),"") | K16: =IFERROR(__xludf.DUMMYFUNCTION("IFERROR((((GOOGLEFINANCE(A16))-(INDEX(GoogleFinance(A16,""PRICE"",$AP$1),2,2)))/(INDEX(GoogleFinance(A16,""PRICE"",$AP$1),2,2))),"""")"),0.9236760124610591) -> 0.92367601 | L16: =IFERROR(((F16-I16)/I16),0) -> -0.084507042 | M16: =IFERROR((VLOOKUP($A16,'Dados StatusInvest'!$A:$AZ,COLUMN(M16)-$A$5,0)*VLOOKUP($A16,'Dados StatusInvest'!$A:$AZ,2,0)/$F16/100),0) -> 0.0878 | N16: =IFERROR((VLOOKUP($A16,'Dados StatusInvest'!$A:$AZ,COLUMN(N16)-$A$5,0)/VLOOKUP($A16,'Dados StatusInvest'!$A:$AZ,2,0)*$F16),"") -> 8.43 | O16: =IFERROR((VLOOKUP($A16,'Dados StatusInvest'!$A:$AZ,COLUMN(O16)-$A$5,0)/VLOOKUP($A16,'Dados StatusInvest'!$A:$AZ,2,0)*$F16),0) -> 21.67 | P16: =IFERROR((VLOOKUP($A16,'Dados StatusInvest'!$A:$AZ,COLUMN(P16)-$A$5,0)/VLOOKUP($A16,'Dados StatusInvest'!$A:$AZ,2,0)*$F16),0) -> 22.81 | Q16: =IFERROR((VLOOKUP($A16,'Dados StatusInvest'!$A:$AZ,COLUMN(Q16)-$A$5,0)/100),0) -> -0.0099 | R16: =VLOOKUP($A16,'Dados StatusInvest'!$A:$AZ,COLUMN(R16)-$A$5,0) -> -0.09 | S16: =IFERROR((VLOOKUP($A16,'Dados StatusInvest'!$A:$AZ,COLUMN(S16)-$A$5,0)),0) -> 1.9 | T16: =IFERROR((VLOOKUP($A16,'Dados StatusInvest'!$A:$AZ,COLUMN(T16)-$A$5,0)/VLOOKUP($A16,'Dados StatusInvest'!$A:$AZ,2,0)*$F16),0) -> 4.62 | U16: =IFERROR((VLOOKUP($A16,'Dados StatusInvest'!$A:$AZ,COLUMN(U16)-$A$5,0)-VLOOKUP($A16,'Dados StatusInvest'!$A:$AZ,COLUMN(U16)-$A$5-1,0)+T16),0) -> -2.72 | V16: =IFERROR((VLOOKUP($A16,'Dados StatusInvest'!$A:$AZ,COLUMN(V16)-$A$5,0)),0) -> 2.4 | W16: =IFERROR((VLOOKUP($A16,'Dados StatusInvest'!$A:$AZ,COLUMN(W16)-$A$5,0)),0) -> 8.69 | X16: =IFERROR((VLOOKUP($A16,'Dados StatusInvest'!$A:$AZ,COLUMN(X16)-$A$5,0)/VLOOKUP($A16,'Dados StatusInvest'!$A:$AZ,2,0)*$F16),0) -> 5.99 | Y16: =IFERROR((VLOOKUP($A16,'Dados StatusInvest'!$A:$AZ,COLUMN(Y16)-$A$5,0)/VLOOKUP($A16,'Dados StatusInvest'!$A:$AZ,2,0)*$F16),0) -> 7.82 | Z16: =IFERROR((VLOOKUP($A16,'Dados StatusInvest'!$A:$AZ,COLUMN(Z16)-$A$5,0)),0) -> 0.69 | AA16: =IFERROR((VLOOKUP($A16,'Dados StatusInvest'!$A:$AZ,COLUMN(AA16)-$A$5,0)),0) -> 0.31 | AB16: =IFERROR((VLOOKUP($A16,'Dados StatusInvest'!$A:$AZ,COLUMN(AB16)-$A$5,0)),0) -> 0.71 | AC16: =IFERROR((VLOOKUP($A16,'Dados StatusInvest'!$A:$AZ,COLUMN(AC16)-$A$5,0)),0) -> 2.05 | AD16: =IFERROR((VLOOKUP($A16,'Dados StatusInvest'!$A:$AZ,COLUMN(AD16)-$A$5,0)),0) -> 6.4 | AE16: =IFERROR((VLOOKUP($A16,'Dados StatusInvest'!$A:$AZ,COLUMN(AE16)-$A$5,0)),0) -> 270396 | AF16: =IFERROR((VLOOKUP($A16,'Dados StatusInvest'!$A:$AZ,COLUMN(AF16)-$A$5,0)),0) -> 6.3 | AG16: =IFERROR((VLOOKUP($A16,'Dados StatusInvest'!$A:$AZ,COLUMN(AG16)-$A$5,0)),0) -> 0.55 | ... AJ16: =IFERROR((VLOOKUP($A16,'Dados StatusInvest'!$A:$AZ,COLUMN(AJ16)-$A$5,0)),0) | AK16: =IFERROR(__xludf.DUMMYFUNCTION("IFERROR(GOOGLEFINANCE($A16,""high""),"""")"),12.35) -> 12.35 | AL16: =IFERROR(__xludf.DUMMYFUNCTION("IFERROR(GOOGLEFINANCE($A16,""low""),"""")"),12.35) -> 12.35 | AM16: =IFERROR(((AK16-AL16)/AL16),0) -> 0 | AN16: =IFERROR(__xludf.DUMMYFUNCTION("IFERROR((GOOGLEFINANCE($A16,""volume"")),0)"),200.0) -> 200 | AO16: =IFERROR(__xludf.DUMMYFUNCTION("IFERROR((GOOGLEFINANCE($A16,""closeyest"")),"""")"),12.35) -> 12.35 | AP16: =IFERROR(__xludf.DUMMYFUNCTION("IFERROR((GOOGLEFINANCE($A16,""shares"")),"""")"),3.39510689E8) -> 339510689
A17: ='Dados StatusInvest'!A12:A631 -> ALPA4 | B17: =IFERROR(__xludf.DUMMYFUNCTION("IFERROR((GOOGLEFINANCE(A17,""name"")),"""")"),"Alpargatas SA Preference Shares") -> Alpargatas SA Preference Shares | C17: =IFERROR((VLOOKUP(LEFT($A17,4),Setor!$A:$E,3,0)),"") -> Consumo Cíclico | D17: =IFERROR((VLOOKUP(LEFT($A17,4),Setor!$A:$E,4,0)),"") -> Tecidos, Vestuário e Calçados | E17: =IFERROR((VLOOKUP(LEFT($A17,4),Setor!$A:$E,5,0)),"") -> Calçados | F17: =IFERROR(__xludf.DUMMYFUNCTION("IFERROR((GOOGLEFINANCE(A17)),"""")"),14.51) -> 14.51 | G17: =IFERROR(__xludf.DUMMYFUNCTION("IFERROR((sparkline(GOOGLEFINANCE($A17,""price"",TODAY()-30,TODAY(),""DAILY""),{""charttype"",""line"";""linewidth"",1;""color"",""#5f88cc""})),"""")"),"") | H17: =IFERROR(__xludf.DUMMYFUNCTION("IFERROR((((GOOGLEFINANCE(A17))-(INDEX(GoogleFinance(A17,""PRICE"",$AQ$1),2,2)))/(INDEX(GoogleFinance(A17,""PRICE"",$AQ$1),2,2))),"""")"),0.12219644238205724) -> 0.12219644 | I17: =IFERROR(__xludf.DUMMYFUNCTION("IFERROR((GOOGLEFINANCE($A17,""high52"")),"""")"),16.22) -> 16.22 | J17: =IFERROR(__xludf.DUMMYFUNCTION("IFERROR((sparkline(GOOGLEFINANCE($A17,""price"",TODAY()-365,TODAY(),""DAILY""),{""charttype"",""line"";""linewidth"",1;""color"",""#5f88cc""})),"""")"),"") | K17: =IFERROR(__xludf.DUMMYFUNCTION("IFERROR((((GOOGLEFINANCE(A17))-(INDEX(GoogleFinance(A17,""PRICE"",$AP$1),2,2)))/(INDEX(GoogleFinance(A17,""PRICE"",$AP$1),2,2))),"""")"),1.1151603498542273) -> 1.1151604 | L17: =IFERROR(((F17-I17)/I17),0) -> -0.1054254 | M17: =IFERROR((VLOOKUP($A17,'Dados StatusInvest'!$A:$AZ,COLUMN(M17)-$A$5,0)*VLOOKUP($A17,'Dados StatusInvest'!$A:$AZ,2,0)/$F17/100),0) -> 0.08925224 | N17: =IFERROR((VLOOKUP($A17,'Dados StatusInvest'!$A:$AZ,COLUMN(N17)-$A$5,0)/VLOOKUP($A17,'Dados StatusInvest'!$A:$AZ,2,0)*$F17),"") -> 8.2928339 | O17: =IFERROR((VLOOKUP($A17,'Dados StatusInvest'!$A:$AZ,COLUMN(O17)-$A$5,0)/VLOOKUP($A17,'Dados StatusInvest'!$A:$AZ,2,0)*$F17),0) -> 25.468739 | P17: =IFERROR((VLOOKUP($A17,'Dados StatusInvest'!$A:$AZ,COLUMN(P17)-$A$5,0)/VLOOKUP($A17,'Dados StatusInvest'!$A:$AZ,2,0)*$F17),0) -> 22.438854 | Q17: =IFERROR((VLOOKUP($A17,'Dados StatusInvest'!$A:$AZ,COLUMN(Q17)-$A$5,0)/100),0) -> -0.0099 | R17: =VLOOKUP($A17,'Dados StatusInvest'!$A:$AZ,COLUMN(R17)-$A$5,0) -> -0.09 | S17: =IFERROR((VLOOKUP($A17,'Dados StatusInvest'!$A:$AZ,COLUMN(S17)-$A$5,0)),0) -> 2.27 | T17: =IFERROR((VLOOKUP($A17,'Dados StatusInvest'!$A:$AZ,COLUMN(T17)-$A$5,0)/VLOOKUP($A17,'Dados StatusInvest'!$A:$AZ,2,0)*$F17),0) -> 5.4301831 | U17: =IFERROR((VLOOKUP($A17,'Dados StatusInvest'!$A:$AZ,COLUMN(U17)-$A$5,0)-VLOOKUP($A17,'Dados StatusInvest'!$A:$AZ,COLUMN(U17)-$A$5-1,0)+T17),0) -> -3.3298169 | V17: =IFERROR((VLOOKUP($A17,'Dados StatusInvest'!$A:$AZ,COLUMN(V17)-$A$5,0)),0) -> 2.4 | W17: =IFERROR((VLOOKUP($A17,'Dados StatusInvest'!$A:$AZ,COLUMN(W17)-$A$5,0)),0) -> 8.69 | X17: =IFERROR((VLOOKUP($A17,'Dados StatusInvest'!$A:$AZ,COLUMN(X17)-$A$5,0)/VLOOKUP($A17,'Dados StatusInvest'!$A:$AZ,2,0)*$F17),0) -> 5.8925356 | Y17: =IFERROR((VLOOKUP($A17,'Dados StatusInvest'!$A:$AZ,COLUMN(Y17)-$A$5,0)/VLOOKUP($A17,'Dados StatusInvest'!$A:$AZ,2,0)*$F17),0) -> 7.6927593 | Z17: =IFERROR((VLOOKUP($A17,'Dados StatusInvest'!$A:$AZ,COLUMN(Z17)-$A$5,0)),0) -> 0.69 | AA17: =IFERROR((VLOOKUP($A17,'Dados StatusInvest'!$A:$AZ,COLUMN(AA17)-$A$5,0)),0) -> 0.31 | AB17: =IFERROR((VLOOKUP($A17,'Dados StatusInvest'!$A:$AZ,COLUMN(AB17)-$A$5,0)),0) -> 0.71 | AC17: =IFERROR((VLOOKUP($A17,'Dados StatusInvest'!$A:$AZ,COLUMN(AC17)-$A$5,0)),0) -> 2.05 | AD17: =IFERROR((VLOOKUP($A17,'Dados StatusInvest'!$A:$AZ,COLUMN(AD17)-$A$5,0)),0) -> 6.4 | AE17: =IFERROR((VLOOKUP($A17,'Dados StatusInvest'!$A:$AZ,COLUMN(AE17)-$A$5,0)),0) -> 36061574 | AF17: =IFERROR((VLOOKUP($A17,'Dados StatusInvest'!$A:$AZ,COLUMN(AF17)-$A$5,0)),0) -> 6.3 | AG17: =IFERROR((VLOOKUP($A17,'Dados StatusInvest'!$A:$AZ,COLUMN(AG17)-$A$5,0)),0) -> 0.55 | ... AJ17: =IFERROR((VLOOKUP($A17,'Dados StatusInvest'!$A:$AZ,COLUMN(AJ17)-$A$5,0)),0) | AK17: =IFERROR(__xludf.DUMMYFUNCTION("IFERROR(GOOGLEFINANCE($A17,""high""),"""")"),14.74) -> 14.74 | AL17: =IFERROR(__xludf.DUMMYFUNCTION("IFERROR(GOOGLEFINANCE($A17,""low""),"""")"),14.36) -> 14.36 | AM17: =IFERROR(((AK17-AL17)/AL17),0) -> 0.026462396 | AN17: =IFERROR(__xludf.DUMMYFUNCTION("IFERROR((GOOGLEFINANCE($A17,""volume"")),0)"),100300.0) -> 100300 | AO17: =IFERROR(__xludf.DUMMYFUNCTION("IFERROR((GOOGLEFINANCE($A17,""closeyest"")),"""")"),14.75) -> 14.75 | AP17: =IFERROR(__xludf.DUMMYFUNCTION("IFERROR((GOOGLEFINANCE($A17,""shares"")),"""")"),"")
A18: ='Dados StatusInvest'!A13:A632 -> ALPK3 | B18: =IFERROR(__xludf.DUMMYFUNCTION("IFERROR((GOOGLEFINANCE(A18,""name"")),"""")"),"Allpark Empreendimentos Prtcpcs Srvcs SA") -> Allpark Empreendimentos Prtcpcs Srvcs SA | C18: =IFERROR((VLOOKUP(LEFT($A18,4),Setor!$A:$E,3,0)),"") -> Bens Industriais | D18: =IFERROR((VLOOKUP(LEFT($A18,4),Setor!$A:$E,4,0)),"") -> Serviços Diversos | E18: =IFERROR((VLOOKUP(LEFT($A18,4),Setor!$A:$E,5,0)),"") -> Serviços Diversos | F18: =IFERROR(__xludf.DUMMYFUNCTION("IFERROR((GOOGLEFINANCE(A18)),"""")"),5.36) -> 5.36 | G18: =IFERROR(__xludf.DUMMYFUNCTION("IFERROR((sparkline(GOOGLEFINANCE($A18,""price"",TODAY()-30,TODAY(),""DAILY""),{""charttype"",""line"";""linewidth"",1;""color"",""#5f88cc""})),"""")"),"") | H18: =IFERROR(__xludf.DUMMYFUNCTION("IFERROR((((GOOGLEFINANCE(A18))-(INDEX(GoogleFinance(A18,""PRICE"",$AQ$1),2,2)))/(INDEX(GoogleFinance(A18,""PRICE"",$AQ$1),2,2))),"""")"),0.16268980477223427) -> 0.1626898 | I18: =IFERROR(__xludf.DUMMYFUNCTION("IFERROR((GOOGLEFINANCE($A18,""high52"")),"""")"),5.37) -> 5.37 | J18: =IFERROR(__xludf.DUMMYFUNCTION("IFERROR((sparkline(GOOGLEFINANCE($A18,""price"",TODAY()-365,TODAY(),""DAILY""),{""charttype"",""line"";""linewidth"",1;""color"",""#5f88cc""})),"""")"),"") | K18: =IFERROR(__xludf.DUMMYFUNCTION("IFERROR((((GOOGLEFINANCE(A18))-(INDEX(GoogleFinance(A18,""PRICE"",$AP$1),2,2)))/(INDEX(GoogleFinance(A18,""PRICE"",$AP$1),2,2))),"""")"),0.7866666666666667) -> 0.78666667 | L18: =IFERROR(((F18-I18)/I18),0) -> -0.0018621974 | M18: =IFERROR((VLOOKUP($A18,'Dados StatusInvest'!$A:$AZ,COLUMN(M18)-$A$5,0)*VLOOKUP($A18,'Dados StatusInvest'!$A:$AZ,2,0)/$F18/100),0) -> 0.13698731 | N18: =IFERROR((VLOOKUP($A18,'Dados StatusInvest'!$A:$AZ,COLUMN(N18)-$A$5,0)/VLOOKUP($A18,'Dados StatusInvest'!$A:$AZ,2,0)*$F18),"") -> 0.081058601 | O18: =IFERROR((VLOOKUP($A18,'Dados StatusInvest'!$A:$AZ,COLUMN(O18)-$A$5,0)/VLOOKUP($A18,'Dados StatusInvest'!$A:$AZ,2,0)*$F18),0) -> 4.7013989 | P18: =IFERROR((VLOOKUP($A18,'Dados StatusInvest'!$A:$AZ,COLUMN(P18)-$A$5,0)/VLOOKUP($A18,'Dados StatusInvest'!$A:$AZ,2,0)*$F18),0) -> 9.443327 | Q18: =IFERROR((VLOOKUP($A18,'Dados StatusInvest'!$A:$AZ,COLUMN(Q18)-$A$5,0)/100),0) -> 0.0469 | R18: =VLOOKUP($A18,'Dados StatusInvest'!$A:$AZ,COLUMN(R18)-$A$5,0) -> 3.29 | S18: =IFERROR((VLOOKUP($A18,'Dados StatusInvest'!$A:$AZ,COLUMN(S18)-$A$5,0)),0) -> 0.64 | T18: =IFERROR((VLOOKUP($A18,'Dados StatusInvest'!$A:$AZ,COLUMN(T18)-$A$5,0)/VLOOKUP($A18,'Dados StatusInvest'!$A:$AZ,2,0)*$F18),0) -> -9.9600756 | U18: =IFERROR((VLOOKUP($A18,'Dados StatusInvest'!$A:$AZ,COLUMN(U18)-$A$5,0)-VLOOKUP($A18,'Dados StatusInvest'!$A:$AZ,COLUMN(U18)-$A$5-1,0)+T18),0) -> -0.70007561 | V18: =IFERROR((VLOOKUP($A18,'Dados StatusInvest'!$A:$AZ,COLUMN(V18)-$A$5,0)),0) -> 0.82 | W18: =IFERROR((VLOOKUP($A18,'Dados StatusInvest'!$A:$AZ,COLUMN(W18)-$A$5,0)),0) -> 0.4 | X18: =IFERROR((VLOOKUP($A18,'Dados StatusInvest'!$A:$AZ,COLUMN(X18)-$A$5,0)/VLOOKUP($A18,'Dados StatusInvest'!$A:$AZ,2,0)*$F18),0) -> 0.050661626 | Y18: =IFERROR((VLOOKUP($A18,'Dados StatusInvest'!$A:$AZ,COLUMN(Y18)-$A$5,0)/VLOOKUP($A18,'Dados StatusInvest'!$A:$AZ,2,0)*$F18),0) -> 12.908582 | Z18: =IFERROR((VLOOKUP($A18,'Dados StatusInvest'!$A:$AZ,COLUMN(Z18)-$A$5,0)),0) -> 0.14 | AA18: =IFERROR((VLOOKUP($A18,'Dados StatusInvest'!$A:$AZ,COLUMN(AA18)-$A$5,0)),0) -> 0.86 | AB18: =IFERROR((VLOOKUP($A18,'Dados StatusInvest'!$A:$AZ,COLUMN(AB18)-$A$5,0)),0) -> 0.7 | AC18: =IFERROR((VLOOKUP($A18,'Dados StatusInvest'!$A:$AZ,COLUMN(AC18)-$A$5,0)),0) -> 7.96 | AD18: =IFERROR((VLOOKUP($A18,'Dados StatusInvest'!$A:$AZ,COLUMN(AD18)-$A$5,0)),0) -> 0 | AE18: =IFERROR((VLOOKUP($A18,'Dados StatusInvest'!$A:$AZ,COLUMN(AE18)-$A$5,0)),0) -> 997644.2 | AF18: =IFERROR((VLOOKUP($A18,'Dados StatusInvest'!$A:$AZ,COLUMN(AF18)-$A$5,0)),0) -> 1.63 | AG18: =IFERROR((VLOOKUP($A18,'Dados StatusInvest'!$A:$AZ,COLUMN(AG18)-$A$5,0)),0) -> 0.01 | ... AJ18: =IFERROR((VLOOKUP($A18,'Dados StatusInvest'!$A:$AZ,COLUMN(AJ18)-$A$5,0)),0) | AK18: =IFERROR(__xludf.DUMMYFUNCTION("IFERROR(GOOGLEFINANCE($A18,""high""),"""")"),5.36) -> 5.36 | AL18: =IFERROR(__xludf.DUMMYFUNCTION("IFERROR(GOOGLEFINANCE($A18,""low""),"""")"),5.24) -> 5.24 | AM18: =IFERROR(((AK18-AL18)/AL18),0) -> 0.022900763 | AN18: =IFERROR(__xludf.DUMMYFUNCTION("IFERROR((GOOGLEFINANCE($A18,""volume"")),0)"),61800.0) -> 61800 | AO18: =IFERROR(__xludf.DUMMYFUNCTION("IFERROR((GOOGLEFINANCE($A18,""closeyest"")),"""")"),5.29) -> 5.29 | AP18: =IFERROR(__xludf.DUMMYFUNCTION("IFERROR((GOOGLEFINANCE($A18,""shares"")),"""")"),2.19305733E8) -> 219305733
A19: ='Dados StatusInvest'!A14:A633 -> ALUP11 | B19: =IFERROR(__xludf.DUMMYFUNCTION("IFERROR((GOOGLEFINANCE(A19,""name"")),"""")"),"Alupar Investimento SA Unit") -> Alupar Investimento SA Unit | C19: =IFERROR((VLOOKUP(LEFT($A19,4),Setor!$A:$E,3,0)),"") -> Utilidade Pública | D19: =IFERROR((VLOOKUP(LEFT($A19,4),Setor!$A:$E,4,0)),"") -> Energia Elétrica | E19: =IFERROR((VLOOKUP(LEFT($A19,4),Setor!$A:$E,5,0)),"") -> Energia Elétrica | F19: =IFERROR(__xludf.DUMMYFUNCTION("IFERROR((GOOGLEFINANCE(A19)),"""")"),35.92) -> 35.92 | G19: =IFERROR(__xludf.DUMMYFUNCTION("IFERROR((sparkline(GOOGLEFINANCE($A19,""price"",TODAY()-30,TODAY(),""DAILY""),{""charttype"",""line"";""linewidth"",1;""color"",""#5f88cc""})),"""")"),"") | H19: =IFERROR(__xludf.DUMMYFUNCTION("IFERROR((((GOOGLEFINANCE(A19))-(INDEX(GoogleFinance(A19,""PRICE"",$AQ$1),2,2)))/(INDEX(GoogleFinance(A19,""PRICE"",$AQ$1),2,2))),"""")"),0.05958702064896765) -> 0.059587021 | I19: =IFERROR(__xludf.DUMMYFUNCTION("IFERROR((GOOGLEFINANCE($A19,""high52"")),"""")"),36.44) -> 36.44 | J19: =IFERROR(__xludf.DUMMYFUNCTION("IFERROR((sparkline(GOOGLEFINANCE($A19,""price"",TODAY()-365,TODAY(),""DAILY""),{""charttype"",""line"";""linewidth"",1;""color"",""#5f88cc""})),"""")"),"") | K19: =IFERROR(__xludf.DUMMYFUNCTION("IFERROR((((GOOGLEFINANCE(A19))-(INDEX(GoogleFinance(A19,""PRICE"",$AP$1),2,2)))/(INDEX(GoogleFinance(A19,""PRICE"",$AP$1),2,2))),"""")"),0.3171983865053173) -> 0.31719839 | L19: =IFERROR(((F19-I19)/I19),0) -> -0.014270033 | M19: =IFERROR((VLOOKUP($A19,'Dados StatusInvest'!$A:$AZ,COLUMN(M19)-$A$5,0)*VLOOKUP($A19,'Dados StatusInvest'!$A:$AZ,2,0)/$F19/100),0) -> 0.71898675 | N19: =IFERROR((VLOOKUP($A19,'Dados StatusInvest'!$A:$AZ,COLUMN(N19)-$A$5,0)/VLOOKUP($A19,'Dados StatusInvest'!$A:$AZ,2,0)*$F19),"") -> 26.574231 | O19: =IFERROR((VLOOKUP($A19,'Dados StatusInvest'!$A:$AZ,COLUMN(O19)-$A$5,0)/VLOOKUP($A19,'Dados StatusInvest'!$A:$AZ,2,0)*$F19),0) -> 3.7920532 | P19: =IFERROR((VLOOKUP($A19,'Dados StatusInvest'!$A:$AZ,COLUMN(P19)-$A$5,0)/VLOOKUP($A19,'Dados StatusInvest'!$A:$AZ,2,0)*$F19),0) -> 6.7480632 | Q19: =IFERROR((VLOOKUP($A19,'Dados StatusInvest'!$A:$AZ,COLUMN(Q19)-$A$5,0)/100),0) -> 0.0297 | R19: =VLOOKUP($A19,'Dados StatusInvest'!$A:$AZ,COLUMN(R19)-$A$5,0) -> 1.03 | S19: =IFERROR((VLOOKUP($A19,'Dados StatusInvest'!$A:$AZ,COLUMN(S19)-$A$5,0)),0) -> 2.73 | T19: =IFERROR((VLOOKUP($A19,'Dados StatusInvest'!$A:$AZ,COLUMN(T19)-$A$5,0)/VLOOKUP($A19,'Dados StatusInvest'!$A:$AZ,2,0)*$F19),0) -> 3.2048324 | U19: =IFERROR((VLOOKUP($A19,'Dados StatusInvest'!$A:$AZ,COLUMN(U19)-$A$5,0)-VLOOKUP($A19,'Dados StatusInvest'!$A:$AZ,COLUMN(U19)-$A$5-1,0)+T19),0) -> -0.48516764 | V19: =IFERROR((VLOOKUP($A19,'Dados StatusInvest'!$A:$AZ,COLUMN(V19)-$A$5,0)),0) -> 2.55 | W19: =IFERROR((VLOOKUP($A19,'Dados StatusInvest'!$A:$AZ,COLUMN(W19)-$A$5,0)),0) -> 12.93 | X19: =IFERROR((VLOOKUP($A19,'Dados StatusInvest'!$A:$AZ,COLUMN(X19)-$A$5,0)/VLOOKUP($A19,'Dados StatusInvest'!$A:$AZ,2,0)*$F19),0) -> 3.6825713 | Y19: =IFERROR((VLOOKUP($A19,'Dados StatusInvest'!$A:$AZ,COLUMN(Y19)-$A$5,0)/VLOOKUP($A19,'Dados StatusInvest'!$A:$AZ,2,0)*$F19),0) -> 10.75908 | Z19: =IFERROR((VLOOKUP($A19,'Dados StatusInvest'!$A:$AZ,COLUMN(Z19)-$A$5,0)),0) -> 0.29 | AA19: =IFERROR((VLOOKUP($A19,'Dados StatusInvest'!$A:$AZ,COLUMN(AA19)-$A$5,0)),0) -> 0.61 | AB19: =IFERROR((VLOOKUP($A19,'Dados StatusInvest'!$A:$AZ,COLUMN(AB19)-$A$5,0)),0) -> 0.14 | AC19: =IFERROR((VLOOKUP($A19,'Dados StatusInvest'!$A:$AZ,COLUMN(AC19)-$A$5,0)),0) -> -2.71 | AD19: =IFERROR((VLOOKUP($A19,'Dados StatusInvest'!$A:$AZ,COLUMN(AD19)-$A$5,0)),0) -> 5.5 | AE19: =IFERROR((VLOOKUP($A19,'Dados StatusInvest'!$A:$AZ,COLUMN(AE19)-$A$5,0)),0) -> 32185667 | AF19: =IFERROR((VLOOKUP($A19,'Dados StatusInvest'!$A:$AZ,COLUMN(AF19)-$A$5,0)),0) -> 27.3 | AG19: =IFERROR((VLOOKUP($A19,'Dados StatusInvest'!$A:$AZ,COLUMN(AG19)-$A$5,0)),0) -> 3.53 | ... AJ19: =IFERROR((VLOOKUP($A19,'Dados StatusInvest'!$A:$AZ,COLUMN(AJ19)-$A$5,0)),0) | AK19: =IFERROR(__xludf.DUMMYFUNCTION("IFERROR(GOOGLEFINANCE($A19,""high""),"""")"),36.11) -> 36.11 | AL19: =IFERROR(__xludf.DUMMYFUNCTION("IFERROR(GOOGLEFINANCE($A19,""low""),"""")"),35.81) -> 35.81 | AM19: =IFERROR(((AK19-AL19)/AL19),0) -> 0.0083775482 | AN19: =IFERROR(__xludf.DUMMYFUNCTION("IFERROR((GOOGLEFINANCE($A19,""volume"")),0)"),9900.0) -> 9900 | AO19: =IFERROR(__xludf.DUMMYFUNCTION("IFERROR((GOOGLEFINANCE($A19,""closeyest"")),"""")"),36.09) -> 36.09 | AP19: =IFERROR(__xludf.DUMMYFUNCTION("IFERROR((GOOGLEFINANCE($A19,""shares"")),"""")"),0.0) -> 0
